Workbook

Sheet Template
A1: Data
A2: Date | B2: Daily Price | G2: Daily Return | M2: 1. Data Information | S2: 2. Variance-covariance matrix | Z2: 3. Portfolio statistics | AC2: Portfolio Var — khai triển (mô phỏng Data.xlsx – Sheet1): = Σ (wᵢ·wⱼ·Covᵢⱼ)
B3: A | C3: B | D3: C | E3: D | F3: E | G3: A | H3: B | I3: C | J3: D | K3: E | N3: Mean | O3: Weights | P3: Var | Q3: Std.Dev | R3: Return | Z3: Portfolio Var | AA3: =SUM(AD4:AH8) -> 0.00035945374 | AD3: A | AE3: B | AF3: C | AG3: D | AH3: E
A4: 44993 | B4: 30300 | C4: 49800 | D4: 37600 | E4: 47600 | F4: 69500 | G4: =B4/B5-1 -> 0.030612245 | H4: =C4/C5-1 -> 0.016326531 | I4: =D4/D5-1 -> 0.093023256 | J4: =E4/E5-1 -> 0.018181818 | K4: =F4/F5-1 -> 0.028106509 | M4: A | N4: =AVERAGE(G4:G455) -> 0.0016523016 | O4: 0.2 | P4: =_xlfn.VAR.S(G4:G455) -> 0.0010938749 | Q4: =SQRT(P4) -> 0.03307378 | R4: =N4*O4 -> 0.00033046031 | T4: A | U4: B | V4: C | W4: D | X4: E | Z4: Portfolio SD | AA4: =SQRT(AA3) -> 0.018959265 | AC4: A | AD4: =INDEX($O$4:$O$8,MATCH($AC4,$M$4:$M$8,0))*INDEX($O$4:$O$8,MATCH(AD$3,$M$4:$M$8,0))*T5 -> 4.3754997e-05 | AE4: =INDEX($O$4:$O$8,MATCH($AC4,$M$4:$M$8,0))*INDEX($O$4:$O$8,MATCH(AE$3,$M$4:$M$8,0))*U5 -> 1.6101298e-05 | AF4: =INDEX($O$4:$O$8,MATCH($AC4,$M$4:$M$8,0))*INDEX($O$4:$O$8,MATCH(AF$3,$M$4:$M$8,0))*V5 -> 2.1899653e-05 | AG4: =INDEX($O$4:$O$8,MATCH($AC4,$M$4:$M$8,0))*INDEX($O$4:$O$8,MATCH(AG$3,$M$4:$M$8,0))*W5 -> 6.4677117e-06 | AH4: =INDEX($O$4:$O$8,MATCH($AC4,$M$4:$M$8,0))*INDEX($O$4:$O$8,MATCH(AH$3,$M$4:$M$8,0))*X5 -> 1.1729887e-05
A5: 44992 | B5: 29400 | C5: 49000 | D5: 34400 | E5: 46750 | F5: 67600 | G5: =B5/B6-1 -> -0.02970297 | H5: =C5/C6-1 -> -0.011099899 | I5: =D5/D6-1 -> 0.039274924 | J5: =E5/E6-1 -> -0.026041667 | K5: =F5/F6-1 -> -0.01744186 | M5: B | N5: =AVERAGE(H4:H455) -> 0.0017525798 | O5: 0.2 | P5: =_xlfn.VAR.S(H4:H455) -> 0.00062029232 | Q5: =SQRT(P5) -> 0.024905668 | R5: =N5*O5 -> 0.00035051595 | S5: A | T5: =_xlfn.COVARIANCE.S(G4:G455,G4:G455) -> 0.0010938749 | U5: =_xlfn.COVARIANCE.S(G4:G455,H4:H455) -> 0.00040253245 | V5: =_xlfn.COVARIANCE.S(G4:G455,I4:I455) -> 0.00054749133 | W5: =_xlfn.COVARIANCE.S(G4:G455,J4:J455) -> 0.00016169279 | X5: =_xlfn.COVARIANCE.S(G4:G455,K4:K455) -> 0.00029324718 | Z5: Portfolio Expected Return | AA5: =$R$9 -> 0.0023298161 | AC5: B | AD5: =INDEX($O$4:$O$8,MATCH($AC5,$M$4:$M$8,0))*INDEX($O$4:$O$8,MATCH(AD$3,$M$4:$M$8,0))*T6 -> 1.6101298e-05 | AE5: =INDEX($O$4:$O$8,MATCH($AC5,$M$4:$M$8,0))*INDEX($O$4:$O$8,MATCH(AE$3,$M$4:$M$8,0))*U6 -> 2.4811693e-05 | AF5: =INDEX($O$4:$O$8,MATCH($AC5,$M$4:$M$8,0))*INDEX($O$4:$O$8,MATCH(AF$3,$M$4:$M$8,0))*V6 -> 1.1943364e-05 | AG5: =INDEX($O$4:$O$8,MATCH($AC5,$M$4:$M$8,0))*INDEX($O$4:$O$8,MATCH(AG$3,$M$4:$M$8,0))*W6 -> 4.7128175e-06 | AH5: =INDEX($O$4:$O$8,MATCH($AC5,$M$4:$M$8,0))*INDEX($O$4:$O$8,MATCH(AH$3,$M$4:$M$8,0))*X6 -> 1.0044978e-05
A6: 44991 | B6: 30300 | C6: 49550 | D6: 33100 | E6: 48000 | F6: 68800 | G6: =B6/B7-1 -> 0.0066445183 | H6: =C6/C7-1 -> 0.0030364372 | I6: =D6/D7-1 -> -0.006006006 | J6: =E6/E7-1 -> -0.016393443 | K6: =F6/F7-1 -> -0.017142857 | M6: C | N6: =AVERAGE(I4:I455) -> 0.0034928059 | O6: 0.2 | P6: =_xlfn.VAR.S(I4:I455) -> 0.0011235409 | Q6: =SQRT(P6) -> 0.033519262 | R6: =N6*O6 -> 0.00069856119 | S6: B | T6: =_xlfn.COVARIANCE.S(H4:H455,G4:G455) -> 0.00040253245 | U6: =_xlfn.COVARIANCE.S(H4:H455,H4:H455) -> 0.00062029232 | V6: =_xlfn.COVARIANCE.S(H4:H455,I4:I455) -> 0.0002985841 | W6: =_xlfn.COVARIANCE.S(H4:H455,J4:J455) -> 0.00011782044 | X6: =_xlfn.COVARIANCE.S(H4:H455,K4:K455) -> 0.00025112445 | Z6: Sharpe ratio | AA6: =(AA5-V28)/AA4 -> 0.11629444 | AC6: C | AD6: =INDEX($O$4:$O$8,MATCH($AC6,$M$4:$M$8,0))*INDEX($O$4:$O$8,MATCH(AD$3,$M$4:$M$8,0))*T7 -> 2.1899653e-05 | AE6: =INDEX($O$4:$O$8,MATCH($AC6,$M$4:$M$8,0))*INDEX($O$4:$O$8,MATCH(AE$3,$M$4:$M$8,0))*U7 -> 1.1943364e-05 | AF6: =INDEX($O$4:$O$8,MATCH($AC6,$M$4:$M$8,0))*INDEX($O$4:$O$8,MATCH(AF$3,$M$4:$M$8,0))*V7 -> 4.4941636e-05 | AG6: =INDEX($O$4:$O$8,MATCH($AC6,$M$4:$M$8,0))*INDEX($O$4:$O$8,MATCH(AG$3,$M$4:$M$8,0))*W7 -> 3.9432352e-06 | AH6: =INDEX($O$4:$O$8,MATCH($AC6,$M$4:$M$8,0))*INDEX($O$4:$O$8,MATCH(AH$3,$M$4:$M$8,0))*X7 -> 8.9458107e-06
A7: 44988 | B7: 30100 | C7: 49400 | D7: 33300 | E7: 48800 | F7: 70000 | G7: =B7/B8-1 -> -0.013114754 | H7: =C7/C8-1 -> -0.012 | I7: =D7/D8-1 -> 0.015243902 | J7: =E7/E8-1 -> 0.0041152263 | K7: =F7/F8-1 -> 0.0014306152 | M7: D | N7: =AVERAGE(J4:J455) -> 0.0011159313 | O7: 0.2 | P7: =_xlfn.VAR.S(J4:J455) -> 0.00024943939 | Q7: =SQRT(P7) -> 0.01579365 | R7: =N7*O7 -> 0.00022318625 | S7: C | T7: =_xlfn.COVARIANCE.S(I4:I455,G4:G455) -> 0.00054749133 | U7: =_xlfn.COVARIANCE.S(I4:I455,H4:H455) -> 0.0002985841 | V7: =_xlfn.COVARIANCE.S(I4:I455,I4:I455) -> 0.0011235409 | W7: =_xlfn.COVARIANCE.S(I4:I455,J4:J455) -> 9.858088e-05 | X7: =_xlfn.COVARIANCE.S(I4:I455,K4:K455) -> 0.00022364527 | AC7: D | AD7: =INDEX($O$4:$O$8,MATCH($AC7,$M$4:$M$8,0))*INDEX($O$4:$O$8,MATCH(AD$3,$M$4:$M$8,0))*T8 -> 6.4677117e-06 | AE7: =INDEX($O$4:$O$8,MATCH($AC7,$M$4:$M$8,0))*INDEX($O$4:$O$8,MATCH(AE$3,$M$4:$M$8,0))*U8 -> 4.7128175e-06 | AF7: =INDEX($O$4:$O$8,MATCH($AC7,$M$4:$M$8,0))*INDEX($O$4:$O$8,MATCH(AF$3,$M$4:$M$8,0))*V8 -> 3.9432352e-06 | AG7: =INDEX($O$4:$O$8,MATCH($AC7,$M$4:$M$8,0))*INDEX($O$4:$O$8,MATCH(AG$3,$M$4:$M$8,0))*W8 -> 9.9775755e-06 | AH7: =INDEX($O$4:$O$8,MATCH($AC7,$M$4:$M$8,0))*INDEX($O$4:$O$8,MATCH(AH$3,$M$4:$M$8,0))*X8 -> 3.7177645e-06
A8: 44987 | B8: 30500 | C8: 50000 | D8: 32800 | E8: 48600 | F8: 69900 | G8: =B8/B9-1 -> 0.06271777 | H8: =C8/C9-1 -> 0.012145749 | I8: =D8/D9-1 -> 0.021806854 | J8: =E8/E9-1 -> 0.0125 | K8: =F8/F9-1 -> 0.040178571 | M8: E | N8: =AVERAGE(K4:K455) -> 0.0036354619 | O8: 0.2 | P8: =_xlfn.VAR.S(K4:K455) -> 0.00092386998 | Q8: =SQRT(P8) -> 0.03039523 | R8: =N8*O8 -> 0.00072709237 | S8: D | T8: =_xlfn.COVARIANCE.S(J4:J455,G4:G455) -> 0.00016169279 | U8: =_xlfn.COVARIANCE.S(J4:J455,H4:H455) -> 0.00011782044 | V8: =_xlfn.COVARIANCE.S(J4:J455,I4:I455) -> 9.858088e-05 | W8: =_xlfn.COVARIANCE.S(J4:J455,J4:J455) -> 0.00024943939 | X8: =_xlfn.COVARIANCE.S(J4:J455,K4:K455) -> 9.2944113e-05 | AC8: E | AD8: =INDEX($O$4:$O$8,MATCH($AC8,$M$4:$M$8,0))*INDEX($O$4:$O$8,MATCH(AD$3,$M$4:$M$8,0))*T9 -> 1.1729887e-05 | AE8: =INDEX($O$4:$O$8,MATCH($AC8,$M$4:$M$8,0))*INDEX($O$4:$O$8,MATCH(AE$3,$M$4:$M$8,0))*U9 -> 1.0044978e-05 | AF8: =INDEX($O$4:$O$8,MATCH($AC8,$M$4:$M$8,0))*INDEX($O$4:$O$8,MATCH(AF$3,$M$4:$M$8,0))*V9 -> 8.9458107e-06 | AG8: =INDEX($O$4:$O$8,MATCH($AC8,$M$4:$M$8,0))*INDEX($O$4:$O$8,MATCH(AG$3,$M$4:$M$8,0))*W9 -> 3.7177645e-06 | AH8: =INDEX($O$4:$O$8,MATCH($AC8,$M$4:$M$8,0))*INDEX($O$4:$O$8,MATCH(AH$3,$M$4:$M$8,0))*X9 -> 3.6954799e-05
A9: 44986 | B9: 28700 | C9: 49400 | D9: 32100 | E9: 48000 | F9: 67200 | G9: =B9/B10-1 -> -0.010344828 | H9: =C9/C10-1 -> 0.042194093 | I9: =D9/D10-1 -> -0.0092592593 | J9: =E9/E10-1 -> -0.010309278 | K9: =F9/F10-1 -> 0.0029850746 | M9: Sum of weights | O9: =SUM(O4:O8) -> 1 | R9: =SUM(R4:R8) -> 0.0023298161 | S9: E | T9: =_xlfn.COVARIANCE.S(K4:K455,G4:G455) -> 0.00029324718 | U9: =_xlfn.COVARIANCE.S(K4:K455,H4:H455) -> 0.00025112445 | V9: =_xlfn.COVARIANCE.S(K4:K455,I4:I455) -> 0.00022364527 | W9: =_xlfn.COVARIANCE.S(K4:K455,J4:J455) -> 9.2944113e-05 | X9: =_xlfn.COVARIANCE.S(K4:K455,K4:K455) -> 0.00092386998 | AC9: Portfolio Var = | AD9: =SUM(AD4:AH8) -> 0.00035945374
A10: 44985 | B10: 29000 | C10: 47400 | D10: 32400 | E10: 48500 | F10: 67000 | G10: =B10/B11-1 -> 0.013986014 | H10: =C10/C11-1 -> -0.047236181 | I10: =D10/D11-1 -> 0.022082019 | J10: =E10/E11-1 -> 0.0041407867 | K10: =F10/F11-1 -> -0.0059347181
A11: 44984 | B11: 28600 | C11: 49750 | D11: 31700 | E11: 48300 | F11: 67400 | G11: =B11/B12-1 -> 0.0035087719 | H11: =C11/C12-1 -> 0.0070850202 | I11: =D11/D12-1 -> -0.021604938 | J11: =E11/E12-1 -> 0.059210526 | K11: =F11/F12-1 -> -0.010279001 | M11: 4. Dữ liệu từ Solver
A12: 44981 | B12: 28500 | C12: 49400 | D12: 32400 | E12: 45600 | F12: 68100 | G12: =B12/B13-1 -> -0.010416667 | H12: =C12/C13-1 -> -0.002020202 | I12: =D12/D13-1 -> -0.018181818 | J12: =E12/E13-1 -> 0.014460512 | K12: =F12/F13-1 -> -0.0058394161 | M12: A
A13: 44980 | B13: 28800 | C13: 49500 | D13: 33000 | E13: 44950 | F13: 68500 | G13: =B13/B14-1 -> -0.01369863 | H13: =C13/C14-1 -> -0.011976048 | I13: =D13/D14-1 -> -0.023668639 | J13: =E13/E14-1 -> -0.012087912 | K13: =F13/F14-1 -> 0.031626506 | M13: B
A14: 44979 | B14: 29200 | C14: 50100 | D14: 33800 | E14: 45500 | F14: 66400 | G14: =B14/B15-1 -> -0.010169492 | H14: =C14/C15-1 -> -0.01183432 | I14: =D14/D15-1 -> -0.025936599 | J14: =E14/E15-1 -> -0.0054644809 | K14: =F14/F15-1 -> 0.026275116 | M14: C
A15: 44978 | B15: 29500 | C15: 50700 | D15: 34700 | E15: 45750 | F15: 64700 | G15: =B15/B16-1 -> 0.027874564 | H15: =C15/C16-1 -> 0.005952381 | I15: =D15/D16-1 -> 0.020588235 | J15: =E15/E16-1 -> 0.013289037 | K15: =F15/F16-1 -> -0.037202381 | M15: D
A16: 44977 | B16: 28700 | C16: 50400 | D16: 34000 | E16: 45150 | F16: 67200 | G16: =B16/B17-1 -> 0 | H16: =C16/C17-1 -> 0.01510574 | I16: =D16/D17-1 -> 0.03030303 | J16: =E16/E17-1 -> 0.026136364 | K16: =F16/F17-1 -> -0.011764706 | M16: E
A17: 44974 | B17: 28700 | C17: 49650 | D17: 33000 | E17: 44000 | F17: 68000 | G17: =B17/B18-1 -> -0.0034722222 | H17: =C17/C18-1 -> -0.007 | I17: =D17/D18-1 -> 0.012269939 | J17: =E17/E18-1 -> 0.025641026 | K17: =F17/F18-1 -> 0
A18: 44973 | B18: 28800 | C18: 50000 | D18: 32600 | E18: 42900 | F18: 68000 | G18: =B18/B19-1 -> -0.01369863 | H18: =C18/C19-1 -> -0.0099009901 | I18: =D18/D19-1 -> -0.006097561 | J18: =E18/E19-1 -> -0.0057937428 | K18: =F18/F19-1 -> 0.0074074074 | M18: Portfolio Var
A19: 44972 | B19: 29200 | C19: 50500 | D19: 32800 | E19: 43150 | F19: 67500 | G19: =B19/B20-1 -> 0.024561404 | H19: =C19/C20-1 -> 0.0059760956 | I19: =D19/D20-1 -> -0.0060606061 | J19: =E19/E20-1 -> -0.0069044879 | K19: =F19/F20-1 -> -0.0088105727 | M19: Portfolio SD
A20: 44971 | B20: 28500 | C20: 50200 | D20: 33000 | E20: 43450 | F20: 68100 | G20: =B20/B21-1 -> 0.0035211268 | H20: =C20/C21-1 -> -0.013752456 | I20: =D20/D21-1 -> -0.0060240964 | J20: =E20/E21-1 -> -0.0068571429 | K20: =F20/F21-1 -> -0.020143885 | M20: Portfolio Exp. Return | N20: 0.0005 | O20: 0.001 | P20: 0.0015 | Q20: 0.002 | R20: 0.0025 | S20: 0.003 | T20: 0.0035 | U20: 0.004 | V20: 0.0045 | W20: 0.005 | X20: 0.0055 | Y20: 0.006
A21: 44970 | B21: 28400 | C21: 50900 | D21: 33200 | E21: 43750 | F21: 69500 | G21: =B21/B22-1 -> 0 | H21: =C21/C22-1 -> -0.019267823 | I21: =D21/D22-1 -> 0 | J21: =E21/E22-1 -> -0.01463964 | K21: =F21/F22-1 -> -0.018361582 | M21: Sharpe ratio
A22: 44967 | B22: 28400 | C22: 51900 | D22: 33200 | E22: 44400 | F22: 70800 | G22: =B22/B23-1 -> -0.013888889 | H22: =C22/C23-1 -> 0.042168675 | I22: =D22/D23-1 -> 0.0060606061 | J22: =E22/E23-1 -> 0.036172695 | K22: =F22/F23-1 -> 0.0042553191
A23: 44966 | B23: 28800 | C23: 49800 | D23: 33000 | E23: 42850 | F23: 70500 | G23: =B23/B24-1 -> 0.0034843206 | H23: =C23/C24-1 -> -0.004 | I23: =D23/D24-1 -> -0.009009009 | J23: =E23/E24-1 -> 0.0046893318 | K23: =F23/F24-1 -> 0.020260492
A24: 44965 | B24: 28700 | C24: 50000 | D24: 33300 | E24: 42650 | F24: 69100 | G24: =B24/B25-1 -> 0.025 | H24: =C24/C25-1 -> 0.002004008 | I24: =D24/D25-1 -> 0.053797468 | J24: =E24/E25-1 -> 0.014268728 | K24: =F24/F25-1 -> -0.007183908 | M24: 5. Optimal risky portfolio | P24: Weight | S24: 6. Combination of Tangent portfolio and RF
A25: 44964 | B25: 28000 | C25: 49900 | D25: 31600 | E25: 42050 | F25: 69600 | G25: =B25/B26-1 -> -0.024390244 | H25: =C25/C26-1 -> -0.002 | I25: =D25/D26-1 -> -0.015576324 | J25: =E25/E26-1 -> -0.0059101655 | K25: =F25/F26-1 -> 0.011627907 | M25: Portfolio Var | P25: A | S25: Weight in RF | V25: 0.5
A26: 44963 | B26: 28700 | C26: 50000 | D26: 32100 | E26: 42300 | F26: 68800 | G26: =B26/B27-1 -> 0.014134276 | H26: =C26/C27-1 -> 0.01010101 | I26: =D26/D27-1 -> -0.0031055901 | J26: =E26/E27-1 -> 0 | K26: =F26/F27-1 -> 0.036144578 | M26: Portfolio SD | P26: B | S26: Portfolio Return with Rf
A27: 44960 | B27: 28300 | C27: 49500 | D27: 32200 | E27: 42300 | F27: 66400 | G27: =B27/B28-1 -> 0.014336918 | H27: =C27/C28-1 -> -0.002016129 | I27: =D27/D28-1 -> 0 | J27: =E27/E28-1 -> -0.0011806375 | K27: =F27/F28-1 -> -0.0015037594 | M27: Portfolio Exp. Return | P27: C | S27: Portfolio Standard Deviation with Rf
A28: 44959 | B28: 27900 | C28: 49600 | D28: 32200 | E28: 42350 | F28: 66500 | G28: =B28/B29-1 -> -0.014134276 | H28: =C28/C29-1 -> 0.002020202 | I28: =D28/D29-1 -> -0.021276596 | J28: =E28/E29-1 -> -0.010514019 | K28: =F28/F29-1 -> 0.013719512 | M28: Sharpe ratio | P28: D | S28: Return/ Daily | V28: =V29/365 -> 0.0001249589
A29: 44958 | B29: 28300 | C29: 49500 | D29: 32900 | E29: 42800 | F29: 65600 | G29: =B29/B30-1 -> 0.080152672 | H29: =C29/C30-1 -> 0.053191489 | I29: =D29/D30-1 -> 0.024922118 | J29: =E29/E30-1 -> 0.0023419204 | K29: =F29/F30-1 -> 0.021806854 | P29: E | S29: Annual Return of Risk-free Rate | V29: 0.04561
A30: 44957 | B30: 26200 | C30: 47000 | D30: 32100 | E30: 42700 | F30: 64200 | G30: =B30/B31-1 -> -0.050724638 | H30: =C30/C31-1 -> -0.0084388186 | I30: =D30/D31-1 -> -0.021341463 | J30: =E30/E31-1 -> -0.016129032 | K30: =F30/F31-1 -> -0.048888889 | P30: Sum | Q30: =SUM(Q25:Q29) -> 0
A31: 44956 | B31: 27600 | C31: 47400 | D31: 32800 | E31: 43400 | F31: 67500 | G31: =B31/B32-1 -> -0.0071942446 | H31: =C31/C32-1 -> -0.0125 | I31: =D31/D32-1 -> 0 | J31: =E31/E32-1 -> -0.013636364 | K31: =F31/F32-1 -> -0.018895349
A32: 44953 | B32: 27800 | C32: 48000 | D32: 32800 | E32: 44000 | F32: 68800 | G32: =B32/B33-1 -> -0.014184397 | H32: =C32/C33-1 -> 0 | I32: =D32/D33-1 -> -0.0030395137 | J32: =E32/E33-1 -> 0.011494253 | K32: =F32/F33-1 -> -0.025495751 | M32: 7. Capital allocation line
A33: 44945 | B33: 28200 | C33: 48000 | D33: 32900 | E33: 43500 | F33: 70600 | G33: =B33/B34-1 -> 0.0035587189 | H33: =C33/C34-1 -> 0.010526316 | I33: =D33/D34-1 -> 0.006116208 | J33: =E33/E34-1 -> 0.01635514 | K33: =F33/F34-1 -> 0.023188406 | M33: Weight of RF | N33: Portfolio SD | O33: Portfolio Exp. Return
A34: 44944 | B34: 28100 | C34: 47500 | D34: 32700 | E34: 42800 | F34: 69000 | G34: =B34/B35-1 -> 0.040740741 | H34: =C34/C35-1 -> -0.0031479538 | I34: =D34/D35-1 -> -0.015060241 | J34: =E34/E35-1 -> -0.011547344 | K34: =F34/F35-1 -> -0.0086206897 | N34: =V27 -> 0 | O34: =V26 -> 0
A35: 44943 | B35: 27000 | C35: 47650 | D35: 33200 | E35: 43300 | F35: 69600 | G35: =B35/B36-1 -> -0.042553191 | H35: =C35/C36-1 -> -0.0093555094 | I35: =D35/D36-1 -> -0.017751479 | J35: =E35/E36-1 -> -0.014789534 | K35: =F35/F36-1 -> -0.030640669 | M35: 1
A36: 44942 | B36: 28200 | C36: 48100 | D36: 33800 | E36: 43950 | F36: 71800 | G36: =B36/B37-1 -> 0 | H36: =C36/C37-1 -> 0.0083857442 | I36: =D36/D37-1 -> 0.015015015 | J36: =E36/E37-1 -> 0.0022805017 | K36: =F36/F37-1 -> 0.021337127 | M36: 0.9
A37: 44939 | B37: 28200 | C37: 47700 | D37: 33300 | E37: 43850 | F37: 70300 | G37: =B37/B38-1 -> -0.0070422535 | H37: =C37/C38-1 -> 0.0063291139 | I37: =D37/D38-1 -> 0.0060422961 | J37: =E37/E38-1 -> 0.012702079 | K37: =F37/F38-1 -> -0.0098591549 | M37: 0.8
A38: 44938 | B38: 28400 | C38: 47400 | D38: 33100 | E38: 43300 | F38: 71000 | G38: =B38/B39-1 -> 0.063670412 | H38: =C38/C39-1 -> 0.0053022269 | I38: =D38/D39-1 -> 0.012232416 | J38: =E38/E39-1 -> -0.022573363 | K38: =F38/F39-1 -> 0.021582734 | M38: 0.7
A39: 44937 | B39: 26700 | C39: 47150 | D39: 32700 | E39: 44300 | F39: 69500 | G39: =B39/B40-1 -> -0.0074349442 | H39: =C39/C40-1 -> 0.0053304904 | I39: =D39/D40-1 -> -0.026785714 | J39: =E39/E40-1 -> -0.015555556 | K39: =F39/F40-1 -> 0.069230769 | M39: 0.6
A40: 44936 | B40: 26900 | C40: 46900 | D40: 33600 | E40: 45000 | F40: 65000 | G40: =B40/B41-1 -> 0.054901961 | H40: =C40/C41-1 -> 0.0021367521 | I40: =D40/D41-1 -> -0.01754386 | J40: =E40/E41-1 -> -0.010989011 | K40: =F40/F41-1 -> -0.0030674847 | M40: 0.5
...

Sheet Shortcut
A1: Data
A2: Date | B2: Daily Price | G2: Daily Return | M2: 1. Data Information | S2: 2. Variance-covariance matrix | Z2: 3. Portfolio statistics
B3: A | C3: B | D3: C | E3: D | F3: E | G3: A | H3: B | I3: C | J3: D | K3: E | N3: Mean | O3: Weights | P3: Var | Q3: Std.Dev | R3: Return | Z3: Portfolio Var
A4: 44993 | B4: 30300 | C4: 49800 | D4: 37600 | E4: 47600 | F4: 69500 | G4: =B4/B5-1 -> 0.030612245 | H4: =C4/C5-1 -> 0.016326531 | I4: =D4/D5-1 -> 0.093023256 | J4: =E4/E5-1 -> 0.018181818 | K4: =F4/F5-1 -> 0.028106509 | M4: A | N4: =AVERAGE(G4:G455) -> 0.0016523016 | O4: 0.2 | P4: =_xlfn.VAR.S(G4:G456) -> 0.0010938749 | Q4: =SQRT(P4) -> 0.03307378 | R4: =O4*N4 -> 0.00033046031 | T4: A | U4: B | V4: C | W4: D | X4: E | Z4: Portfolio SD
A5: 44992 | B5: 29400 | C5: 49000 | D5: 34400 | E5: 46750 | F5: 67600 | G5: =B5/B6-1 -> -0.02970297 | H5: =C5/C6-1 -> -0.011099899 | I5: =D5/D6-1 -> 0.039274924 | J5: =E5/E6-1 -> -0.026041667 | K5: =F5/F6-1 -> -0.01744186 | M5: B | N5: =AVERAGE(H4:H455) -> 0.0017525798 | O5: 0.2 | P5: =_xlfn.VAR.S(H4:H456) -> 0.00062029232 | Q5: =SQRT(P5) -> 0.024905668 | R5: =O5*N5 -> 0.00035051595 | S5: A | T5: =_xlfn.VAR.S(Shortcut!$G$4:$G$455) -> 0.0010938749 | U5: =T6 -> 0.00040253245 | V5: =T7 -> 0.00054749133 | W5: =T8 -> 0.00016169279 | X5: =T9 -> 0.00029324718 | Z5: Portfolio Expected Return
A6: 44991 | B6: 30300 | C6: 49550 | D6: 33100 | E6: 48000 | F6: 68800 | G6: =B6/B7-1 -> 0.0066445183 | H6: =C6/C7-1 -> 0.0030364372 | I6: =D6/D7-1 -> -0.006006006 | J6: =E6/E7-1 -> -0.016393443 | K6: =F6/F7-1 -> -0.017142857 | M6: C | N6: =AVERAGE(I4:I455) -> 0.0034928059 | O6: 0.2 | P6: =_xlfn.VAR.S(I4:I456) -> 0.0011235409 | Q6: =SQRT(P6) -> 0.033519262 | R6: =O6*N6 -> 0.00069856119 | S6: B | T6: =_xlfn.COVARIANCE.S(G4:G455,H4:H455) -> 0.00040253245 | U6: =_xlfn.VAR.S(Shortcut!$H$4:$H$455) -> 0.00062029232 | V6: =U7 -> 0.0002985841 | W6: =U8 -> 0.00011782044 | X6: =U9 -> 0.00025112445 | Z6: Sharpe ratio
A7: 44988 | B7: 30100 | C7: 49400 | D7: 33300 | E7: 48800 | F7: 70000 | G7: =B7/B8-1 -> -0.013114754 | H7: =C7/C8-1 -> -0.012 | I7: =D7/D8-1 -> 0.015243902 | J7: =E7/E8-1 -> 0.0041152263 | K7: =F7/F8-1 -> 0.0014306152 | M7: D | O7: 0.2 | S7: C | T7: =_xlfn.COVARIANCE.S(G4:G455,I4:I455) -> 0.00054749133 | U7: =_xlfn.COVARIANCE.S(I4:I455,H4:H455) -> 0.0002985841 | V7: =_xlfn.VAR.S(Shortcut!$I$4:$I$455) -> 0.0011235409 | W7: =V8 -> 9.858088e-05 | X7: =V9 -> 0.00022364527
A8: 44987 | B8: 30500 | C8: 50000 | D8: 32800 | E8: 48600 | F8: 69900 | G8: =B8/B9-1 -> 0.06271777 | H8: =C8/C9-1 -> 0.012145749 | I8: =D8/D9-1 -> 0.021806854 | J8: =E8/E9-1 -> 0.0125 | K8: =F8/F9-1 -> 0.040178571 | M8: E | O8: 0.2 | S8: D | T8: =_xlfn.COVARIANCE.S(G4:G455,J4:J455) -> 0.00016169279 | U8: =_xlfn.COVARIANCE.S(J4:J455,H4:H455) -> 0.00011782044 | V8: =_xlfn.COVARIANCE.S(I4:I455,J4:J455) -> 9.858088e-05
A9: 44986 | B9: 28700 | C9: 49400 | D9: 32100 | E9: 48000 | F9: 67200 | G9: =B9/B10-1 -> -0.010344828 | H9: =C9/C10-1 -> 0.042194093 | I9: =D9/D10-1 -> -0.0092592593 | J9: =E9/E10-1 -> -0.010309278 | K9: =F9/F10-1 -> 0.0029850746 | M9: Sum of weights | O9: =SUM(O4:O8) -> 1 | R9: =SUM(R4:R8) -> 0.0013795375 | S9: E | T9: =_xlfn.COVARIANCE.S(G4:G455,K4:K455) -> 0.00029324718 | U9: =_xlfn.COVARIANCE.S(K4:K455,H4:H455) -> 0.00025112445 | V9: =_xlfn.COVARIANCE.S(I4:I455,K4:K455) -> 0.00022364527
A10: 44985 | B10: 29000 | C10: 47400 | D10: 32400 | E10: 48500 | F10: 67000 | G10: =B10/B11-1 -> 0.013986014 | H10: =C10/C11-1 -> -0.047236181 | I10: =D10/D11-1 -> 0.022082019 | J10: =E10/E11-1 -> 0.0041407867 | K10: =F10/F11-1 -> -0.0059347181
A11: 44984 | B11: 28600 | C11: 49750 | D11: 31700 | E11: 48300 | F11: 67400 | G11: =B11/B12-1 -> 0.0035087719 | H11: =C11/C12-1 -> 0.0070850202 | I11: =D11/D12-1 -> -0.021604938 | J11: =E11/E12-1 -> 0.059210526 | K11: =F11/F12-1 -> -0.010279001 | M11: 4. Dữ liệu từ Solver
A12: 44981 | B12: 28500 | C12: 49400 | D12: 32400 | E12: 45600 | F12: 68100 | G12: =B12/B13-1 -> -0.010416667 | H12: =C12/C13-1 -> -0.002020202 | I12: =D12/D13-1 -> -0.018181818 | J12: =E12/E13-1 -> 0.014460512 | K12: =F12/F13-1 -> -0.0058394161 | M12: A | N12: 0.080434977 | O12: 0.029048755 | P12: -0.02233144 | Q12: -0.073711589 | R12: -0.12509169 | S12: -0.1764718 | T12: -0.22785194 | U12: -0.27923209 | V12: -0.33061225 | W12: -0.3819924
A13: 44980 | B13: 28800 | C13: 49500 | D13: 33000 | E13: 44950 | F13: 68500 | G13: =B13/B14-1 -> -0.01369863 | H13: =C13/C14-1 -> -0.011976048 | I13: =D13/D14-1 -> -0.023668639 | J13: =E13/E14-1 -> -0.012087912 | K13: =F13/F14-1 -> 0.031626506 | M13: B | N13: 0.20450929 | O13: 0.17576503 | P13: 0.147008 | Q13: 0.11825098 | R13: 0.089493918 | S13: 0.060736864 | T13: 0.031979843 | U13: 0.0032228316 | V13: -0.025534222 | W13: -0.054291264
A14: 44979 | B14: 29200 | C14: 50100 | D14: 33800 | E14: 45500 | F14: 66400 | G14: =B14/B15-1 -> -0.010169492 | H14: =C14/C15-1 -> -0.01183432 | I14: =D14/D15-1 -> -0.025936599 | J14: =E14/E15-1 -> -0.0054644809 | K14: =F14/F15-1 -> 0.026275116 | M14: C | N14: -0.1533456 | O14: -0.050873822 | P14: 0.051598221 | Q14: 0.15407027 | R14: 0.25654234 | S14: 0.35901442 | T14: 0.46148647 | U14: 0.56395852 | V14: 0.66643058 | W14: 0.76890263
A15: 44978 | B15: 29500 | C15: 50700 | D15: 34700 | E15: 45750 | F15: 64700 | G15: =B15/B16-1 -> 0.027874564 | H15: =C15/C16-1 -> 0.005952381 | I15: =D15/D16-1 -> 0.020588235 | J15: =E15/E16-1 -> 0.013289037 | K15: =F15/F16-1 -> -0.037202381 | M15: D | N15: 1.0370008 | O15: 0.89467703 | P15: 0.75235806 | Q15: 0.61003905 | R15: 0.46772003 | S15: 0.32540102 | T15: 0.18308201 | U15: 0.040762989 | V15: -0.10155599 | W15: -0.24387497
A16: 44977 | B16: 28700 | C16: 50400 | D16: 34000 | E16: 45150 | F16: 67200 | G16: =B16/B17-1 -> 0 | H16: =C16/C17-1 -> 0.01510574 | I16: =D16/D17-1 -> 0.03030303 | J16: =E16/E17-1 -> 0.026136364 | K16: =F16/F17-1 -> -0.011764706 | M16: E | N16: -0.16859951 | O16: -0.048616987 | P16: 0.071367158 | Q16: 0.19135129 | R16: 0.31133539 | S16: 0.4313195 | T16: 0.55130362 | U16: 0.67128774 | V16: 0.79127187 | W16: 0.91125601
A17: 44974 | B17: 28700 | C17: 49650 | D17: 33000 | E17: 44000 | F17: 68000 | G17: =B17/B18-1 -> -0.0034722222 | H17: =C17/C18-1 -> -0.007 | I17: =D17/D18-1 -> 0.012269939 | J17: =E17/E18-1 -> 0.025641026 | K17: =F17/F18-1 -> 0
A18: 44973 | B18: 28800 | C18: 50000 | D18: 32600 | E18: 42900 | F18: 68000 | G18: =B18/B19-1 -> -0.01369863 | H18: =C18/C19-1 -> -0.0099009901 | I18: =D18/D19-1 -> -0.006097561 | J18: =E18/E19-1 -> -0.0057937428 | K18: =F18/F19-1 -> 0.0074074074 | M18: Portfolio Var
A19: 44972 | B19: 29200 | C19: 50500 | D19: 32800 | E19: 43150 | F19: 67500 | G19: =B19/B20-1 -> 0.024561404 | H19: =C19/C20-1 -> 0.0059760956 | I19: =D19/D20-1 -> -0.0060606061 | J19: =E19/E20-1 -> -0.0069044879 | K19: =F19/F20-1 -> -0.0088105727 | M19: Portfolio SD
A20: 44971 | B20: 28500 | C20: 50200 | D20: 33000 | E20: 43450 | F20: 68100 | G20: =B20/B21-1 -> 0.0035211268 | H20: =C20/C21-1 -> -0.013752456 | I20: =D20/D21-1 -> -0.0060240964 | J20: =E20/E21-1 -> -0.0068571429 | K20: =F20/F21-1 -> -0.020143885 | M20: Portfolio Exp. Return | N20: 0.0005 | O20: 0.001 | P20: 0.0015 | Q20: 0.002 | R20: 0.0025 | S20: 0.003 | T20: 0.0035 | U20: 0.004 | V20: 0.0045 | W20: 0.005 | X20: 0.0055 | Y20: 0.006
A21: 44970 | B21: 28400 | C21: 50900 | D21: 33200 | E21: 43750 | F21: 69500 | G21: =B21/B22-1 -> 0 | H21: =C21/C22-1 -> -0.019267823 | I21: =D21/D22-1 -> 0 | J21: =E21/E22-1 -> -0.01463964 | K21: =F21/F22-1 -> -0.018361582 | M21: Sharpe ratio
A22: 44967 | B22: 28400 | C22: 51900 | D22: 33200 | E22: 44400 | F22: 70800 | G22: =B22/B23-1 -> -0.013888889 | H22: =C22/C23-1 -> 0.042168675 | I22: =D22/D23-1 -> 0.0060606061 | J22: =E22/E23-1 -> 0.036172695 | K22: =F22/F23-1 -> 0.0042553191
A23: 44966 | B23: 28800 | C23: 49800 | D23: 33000 | E23: 42850 | F23: 70500 | G23: =B23/B24-1 -> 0.0034843206 | H23: =C23/C24-1 -> -0.004 | I23: =D23/D24-1 -> -0.009009009 | J23: =E23/E24-1 -> 0.0046893318 | K23: =F23/F24-1 -> 0.020260492
A24: 44965 | B24: 28700 | C24: 50000 | D24: 33300 | E24: 42650 | F24: 69100 | G24: =B24/B25-1 -> 0.025 | H24: =C24/C25-1 -> 0.002004008 | I24: =D24/D25-1 -> 0.053797468 | J24: =E24/E25-1 -> 0.014268728 | K24: =F24/F25-1 -> -0.007183908 | M24: 5. Optimal risky portfolio | P24: Weight | S24: 6. Combination of Tangent portfolio and RF
A25: 44964 | B25: 28000 | C25: 49900 | D25: 31600 | E25: 42050 | F25: 69600 | G25: =B25/B26-1 -> -0.024390244 | H25: =C25/C26-1 -> -0.002 | I25: =D25/D26-1 -> -0.015576324 | J25: =E25/E26-1 -> -0.0059101655 | K25: =F25/F26-1 -> 0.011627907 | M25: Portfolio Var | P25: A | S25: Weight in RF | V25: 0.5
A26: 44963 | B26: 28700 | C26: 50000 | D26: 32100 | E26: 42300 | F26: 68800 | G26: =B26/B27-1 -> 0.014134276 | H26: =C26/C27-1 -> 0.01010101 | I26: =D26/D27-1 -> -0.0031055901 | J26: =E26/E27-1 -> 0 | K26: =F26/F27-1 -> 0.036144578 | M26: Portfolio SD | P26: B | S26: Portfolio Return with Rf
A27: 44960 | B27: 28300 | C27: 49500 | D27: 32200 | E27: 42300 | F27: 66400 | G27: =B27/B28-1 -> 0.014336918 | H27: =C27/C28-1 -> -0.002016129 | I27: =D27/D28-1 -> 0 | J27: =E27/E28-1 -> -0.0011806375 | K27: =F27/F28-1 -> -0.0015037594 | M27: Portfolio Exp. Return | P27: C | S27: Portfolio Standard Deviation with Rf
A28: 44959 | B28: 27900 | C28: 49600 | D28: 32200 | E28: 42350 | F28: 66500 | G28: =B28/B29-1 -> -0.014134276 | H28: =C28/C29-1 -> 0.002020202 | I28: =D28/D29-1 -> -0.021276596 | J28: =E28/E29-1 -> -0.010514019 | K28: =F28/F29-1 -> 0.013719512 | M28: Sharpe ratio | P28: D | S28: Return/ Daily | V28: =V29/365 -> 0.0001249589
A29: 44958 | B29: 28300 | C29: 49500 | D29: 32900 | E29: 42800 | F29: 65600 | G29: =B29/B30-1 -> 0.080152672 | H29: =C29/C30-1 -> 0.053191489 | I29: =D29/D30-1 -> 0.024922118 | J29: =E29/E30-1 -> 0.0023419204 | K29: =F29/F30-1 -> 0.021806854 | P29: E | S29: Annual Return of Risk-free Rate | V29: 0.04561
A30: 44957 | B30: 26200 | C30: 47000 | D30: 32100 | E30: 42700 | F30: 64200 | G30: =B30/B31-1 -> -0.050724638 | H30: =C30/C31-1 -> -0.0084388186 | I30: =D30/D31-1 -> -0.021341463 | J30: =E30/E31-1 -> -0.016129032 | K30: =F30/F31-1 -> -0.048888889 | P30: Sum | Q30: =SUM(Q25:Q29) -> 0
A31: 44956 | B31: 27600 | C31: 47400 | D31: 32800 | E31: 43400 | F31: 67500 | G31: =B31/B32-1 -> -0.0071942446 | H31: =C31/C32-1 -> -0.0125 | I31: =D31/D32-1 -> 0 | J31: =E31/E32-1 -> -0.013636364 | K31: =F31/F32-1 -> -0.018895349
A32: 44953 | B32: 27800 | C32: 48000 | D32: 32800 | E32: 44000 | F32: 68800 | G32: =B32/B33-1 -> -0.014184397 | H32: =C32/C33-1 -> 0 | I32: =D32/D33-1 -> -0.0030395137 | J32: =E32/E33-1 -> 0.011494253 | K32: =F32/F33-1 -> -0.025495751 | M32: 7. Capital allocation line
A33: 44945 | B33: 28200 | C33: 48000 | D33: 32900 | E33: 43500 | F33: 70600 | G33: =B33/B34-1 -> 0.0035587189 | H33: =C33/C34-1 -> 0.010526316 | I33: =D33/D34-1 -> 0.006116208 | J33: =E33/E34-1 -> 0.01635514 | K33: =F33/F34-1 -> 0.023188406 | M33: Weight of RF | N33: Portfolio SD | O33: Portfolio Exp. Return
A34: 44944 | B34: 28100 | C34: 47500 | D34: 32700 | E34: 42800 | F34: 69000 | G34: =B34/B35-1 -> 0.040740741 | H34: =C34/C35-1 -> -0.0031479538 | I34: =D34/D35-1 -> -0.015060241 | J34: =E34/E35-1 -> -0.011547344 | K34: =F34/F35-1 -> -0.0086206897 | N34: =V27 -> 0 | O34: =V26 -> 0
A35: 44943 | B35: 27000 | C35: 47650 | D35: 33200 | E35: 43300 | F35: 69600 | G35: =B35/B36-1 -> -0.042553191 | H35: =C35/C36-1 -> -0.0093555094 | I35: =D35/D36-1 -> -0.017751479 | J35: =E35/E36-1 -> -0.014789534 | K35: =F35/F36-1 -> -0.030640669 | M35: 1 | N35: 0 | O35: 0
A36: 44942 | B36: 28200 | C36: 48100 | D36: 33800 | E36: 43950 | F36: 71800 | G36: =B36/B37-1 -> 0 | H36: =C36/C37-1 -> 0.0083857442 | I36: =D36/D37-1 -> 0.015015015 | J36: =E36/E37-1 -> 0.0022805017 | K36: =F36/F37-1 -> 0.021337127 | M36: 0.9 | N36: 0 | O36: 0
A37: 44939 | B37: 28200 | C37: 47700 | D37: 33300 | E37: 43850 | F37: 70300 | G37: =B37/B38-1 -> -0.0070422535 | H37: =C37/C38-1 -> 0.0063291139 | I37: =D37/D38-1 -> 0.0060422961 | J37: =E37/E38-1 -> 0.012702079 | K37: =F37/F38-1 -> -0.0098591549 | M37: 0.8 | N37: 0 | O37: 0
A38: 44938 | B38: 28400 | C38: 47400 | D38: 33100 | E38: 43300 | F38: 71000 | G38: =B38/B39-1 -> 0.063670412 | H38: =C38/C39-1 -> 0.0053022269 | I38: =D38/D39-1 -> 0.012232416 | J38: =E38/E39-1 -> -0.022573363 | K38: =F38/F39-1 -> 0.021582734 | M38: 0.7 | N38: 0 | O38: 0
A39: 44937 | B39: 26700 | C39: 47150 | D39: 32700 | E39: 44300 | F39: 69500 | G39: =B39/B40-1 -> -0.0074349442 | H39: =C39/C40-1 -> 0.0053304904 | I39: =D39/D40-1 -> -0.026785714 | J39: =E39/E40-1 -> -0.015555556 | K39: =F39/F40-1 -> 0.069230769 | M39: 0.6 | N39: 0 | O39: 0
A40: 44936 | B40: 26900 | C40: 46900 | D40: 33600 | E40: 45000 | F40: 65000 | G40: =B40/B41-1 -> 0.054901961 | H40: =C40/C41-1 -> 0.0021367521 | I40: =D40/D41-1 -> -0.01754386 | J40: =E40/E41-1 -> -0.010989011 | K40: =F40/F41-1 -> -0.0030674847 | M40: 0.5 | N40: 0 | O40: 0
...

Sheet Final
A1: Data
A2: Date | B2: Daily Price | G2: Daily Return | M2: 1. Data Information | S2: 2. Variance-covariance matrix | Z2: 3. Portfolio statistics
B3: A | C3: B | D3: C | E3: D | F3: E | G3: A | H3: B | I3: C | J3: D | K3: E | N3: Mean | O3: Weights | P3: Var | Q3: Std.Dev | R3: Return | Z3: Portfolio Var | AA3: {=MMULT(MMULT(TRANSPOSE(O4:O8),T5:X9),O4:O8)} -> 0.0020778502
A4: 44993 | B4: 30300 | C4: 49800 | D4: 37600 | E4: 47600 | F4: 69500 | G4: =B4/B5-1 -> 0.030612245 | H4: =C4/C5-1 -> 0.016326531 | I4: =D4/D5-1 -> 0.093023256 | J4: =E4/E5-1 -> 0.018181818 | K4: =F4/F5-1 -> 0.028106509 | M4: A | N4: =AVERAGE(G4:G455) -> 0.0016523016 | O4: -0.48475269 | P4: =_xlfn.VAR.S(G4:G456) -> 0.0010938749 | Q4: =SQRT(P4) -> 0.03307378 | R4: =O4*N4 -> -0.00080095762 | T4: A | U4: B | V4: C | W4: D | X4: E | Z4: Portfolio SD | AA4: =SQRT(AA3) -> 0.045583442
A5: 44992 | B5: 29400 | C5: 49000 | D5: 34400 | E5: 46750 | F5: 67600 | G5: =B5/B6-1 -> -0.02970297 | H5: =C5/C6-1 -> -0.011099899 | I5: =D5/D6-1 -> 0.039274924 | J5: =E5/E6-1 -> -0.026041667 | K5: =F5/F6-1 -> -0.01744186 | M5: B | N5: =AVERAGE(H4:H455) -> 0.0017525798 | O5: -0.11180532 | P5: =_xlfn.VAR.S(H4:H456) -> 0.00062029232 | Q5: =SQRT(P5) -> 0.024905668 | R5: =O5*N5 -> -0.00019594775 | S5: A | T5: =_xlfn.VAR.S(Final!$G$4:$G$455) -> 0.0010938749 | U5: =T6 -> 0.00040253245 | V5: =T7 -> 0.00054749133 | W5: =T8 -> 0.00016169279 | X5: =T9 -> 0.00029324718 | Z5: Portfolio Expected Return | AA5: =$R$9 -> 0.0060000001
A6: 44991 | B6: 30300 | C6: 49550 | D6: 33100 | E6: 48000 | F6: 68800 | G6: =B6/B7-1 -> 0.0066445183 | H6: =C6/C7-1 -> 0.0030364372 | I6: =D6/D7-1 -> -0.006006006 | J6: =E6/E7-1 -> -0.016393443 | K6: =F6/F7-1 -> -0.017142857 | M6: C | N6: =AVERAGE(I4:I455) -> 0.0034928059 | O6: 0.9738467 | P6: =_xlfn.VAR.S(I4:I456) -> 0.0011235409 | Q6: =SQRT(P6) -> 0.033519262 | R6: =O6*N6 -> 0.0034014576 | S6: B | T6: =_xlfn.COVARIANCE.S(G4:G455,H4:H455) -> 0.00040253245 | U6: =_xlfn.VAR.S(Final!$H$4:$H$455) -> 0.00062029232 | V6: =U7 -> 0.0002985841 | W6: =U8 -> 0.00011782044 | X6: =U9 -> 0.00025112445 | Z6: Sharpe ratio | AA6: =(AA5-V28)/AA4 -> 0.12888542
A7: 44988 | B7: 30100 | C7: 49400 | D7: 33300 | E7: 48800 | F7: 70000 | G7: =B7/B8-1 -> -0.013114754 | H7: =C7/C8-1 -> -0.012 | I7: =D7/D8-1 -> 0.015243902 | J7: =E7/E8-1 -> 0.0041152263 | K7: =F7/F8-1 -> 0.0014306152 | M7: D | N7: =AVERAGE(J4:J455) -> 0.0011159313 | O7: -0.52851301 | P7: =_xlfn.VAR.S(J4:J456) -> 0.00024943939 | Q7: =SQRT(P7) -> 0.01579365 | R7: =O7*N7 -> -0.00058978419 | S7: C | T7: =_xlfn.COVARIANCE.S(G4:G455,I4:I455) -> 0.00054749133 | U7: =_xlfn.COVARIANCE.S(I4:I455,H4:H455) -> 0.0002985841 | V7: =_xlfn.VAR.S(Final!$I$4:$I$455) -> 0.0011235409 | W7: =V8 -> 9.858088e-05 | X7: =V9 -> 0.00022364527
A8: 44987 | B8: 30500 | C8: 50000 | D8: 32800 | E8: 48600 | F8: 69900 | G8: =B8/B9-1 -> 0.06271777 | H8: =C8/C9-1 -> 0.012145749 | I8: =D8/D9-1 -> 0.021806854 | J8: =E8/E9-1 -> 0.0125 | K8: =F8/F9-1 -> 0.040178571 | M8: E | N8: =AVERAGE(K4:K455) -> 0.0036354619 | O8: 1.1512243 | P8: =_xlfn.VAR.S(K4:K456) -> 0.00092386998 | Q8: =SQRT(P8) -> 0.03039523 | R8: =O8*N8 -> 0.0041852321 | S8: D | T8: =_xlfn.COVARIANCE.S(G4:G455,J4:J455) -> 0.00016169279 | U8: =_xlfn.COVARIANCE.S(J4:J455,H4:H455) -> 0.00011782044 | V8: =_xlfn.COVARIANCE.S(I4:I455,J4:J455) -> 9.858088e-05 | W8: =_xlfn.VAR.S(Final!$J$4:$J$455) -> 0.00024943939 | X8: =W9 -> 9.2944113e-05
A9: 44986 | B9: 28700 | C9: 49400 | D9: 32100 | E9: 48000 | F9: 67200 | G9: =B9/B10-1 -> -0.010344828 | H9: =C9/C10-1 -> 0.042194093 | I9: =D9/D10-1 -> -0.0092592593 | J9: =E9/E10-1 -> -0.010309278 | K9: =F9/F10-1 -> 0.0029850746 | M9: Sum of weights | O9: =SUM(O4:O8) -> 1 | R9: =SUM(R4:R8) -> 0.0060000001 | S9: E | T9: =_xlfn.COVARIANCE.S(G4:G455,K4:K455) -> 0.00029324718 | U9: =_xlfn.COVARIANCE.S(K4:K455,H4:H455) -> 0.00025112445 | V9: =_xlfn.COVARIANCE.S(I4:I455,K4:K455) -> 0.00022364527 | W9: =_xlfn.COVARIANCE.S(K4:K455,J4:J455) -> 9.2944113e-05 | X9: =_xlfn.VAR.S(Final!$K$4:$K$455) -> 0.00092386998
A10: 44985 | B10: 29000 | C10: 47400 | D10: 32400 | E10: 48500 | F10: 67000 | G10: =B10/B11-1 -> 0.013986014 | H10: =C10/C11-1 -> -0.047236181 | I10: =D10/D11-1 -> 0.022082019 | J10: =E10/E11-1 -> 0.0041407867 | K10: =F10/F11-1 -> -0.0059347181
A11: 44984 | B11: 28600 | C11: 49750 | D11: 31700 | E11: 48300 | F11: 67400 | G11: =B11/B12-1 -> 0.0035087719 | H11: =C11/C12-1 -> 0.0070850202 | I11: =D11/D12-1 -> -0.021604938 | J11: =E11/E12-1 -> 0.059210526 | K11: =F11/F12-1 -> -0.010279001 | M11: 4. Dữ liệu từ Solver
A12: 44981 | B12: 28500 | C12: 49400 | D12: 32400 | E12: 45600 | F12: 68100 | G12: =B12/B13-1 -> -0.010416667 | H12: =C12/C13-1 -> -0.002020202 | I12: =D12/D13-1 -> -0.018181818 | J12: =E12/E13-1 -> 0.014460512 | K12: =F12/F13-1 -> -0.0058394161 | M12: A | N12: 0.080434977 | O12: 0.029048755 | P12: -0.02233144 | Q12: -0.073711589 | R12: -0.12509169 | S12: -0.1764718 | T12: -0.22785194 | U12: -0.27923209 | V12: -0.33061225 | W12: -0.3819924 | X12: -0.43337255 | Y12: -0.4847527
A13: 44980 | B13: 28800 | C13: 49500 | D13: 33000 | E13: 44950 | F13: 68500 | G13: =B13/B14-1 -> -0.01369863 | H13: =C13/C14-1 -> -0.011976048 | I13: =D13/D14-1 -> -0.023668639 | J13: =E13/E14-1 -> -0.012087912 | K13: =F13/F14-1 -> 0.031626506 | M13: B | N13: 0.20450929 | O13: 0.17576503 | P13: 0.147008 | Q13: 0.11825098 | R13: 0.089493918 | S13: 0.060736864 | T13: 0.031979843 | U13: 0.0032228316 | V13: -0.025534222 | W13: -0.054291264 | X13: -0.083048279 | Y13: -0.11180531
A14: 44979 | B14: 29200 | C14: 50100 | D14: 33800 | E14: 45500 | F14: 66400 | G14: =B14/B15-1 -> -0.010169492 | H14: =C14/C15-1 -> -0.01183432 | I14: =D14/D15-1 -> -0.025936599 | J14: =E14/E15-1 -> -0.0054644809 | K14: =F14/F15-1 -> 0.026275116 | M14: C | N14: -0.1533456 | O14: -0.050873822 | P14: 0.051598221 | Q14: 0.15407027 | R14: 0.25654234 | S14: 0.35901442 | T14: 0.46148647 | U14: 0.56395852 | V14: 0.66643058 | W14: 0.76890263 | X14: 0.87137468 | Y14: 0.97384673
A15: 44978 | B15: 29500 | C15: 50700 | D15: 34700 | E15: 45750 | F15: 64700 | G15: =B15/B16-1 -> 0.027874564 | H15: =C15/C16-1 -> 0.005952381 | I15: =D15/D16-1 -> 0.020588235 | J15: =E15/E16-1 -> 0.013289037 | K15: =F15/F16-1 -> -0.037202381 | M15: D | N15: 1.0370008 | O15: 0.89467703 | P15: 0.75235806 | Q15: 0.61003905 | R15: 0.46772003 | S15: 0.32540102 | T15: 0.18308201 | U15: 0.040762989 | V15: -0.10155599 | W15: -0.24387497 | X15: -0.38619399 | Y15: -0.52851299
A16: 44977 | B16: 28700 | C16: 50400 | D16: 34000 | E16: 45150 | F16: 67200 | G16: =B16/B17-1 -> 0 | H16: =C16/C17-1 -> 0.01510574 | I16: =D16/D17-1 -> 0.03030303 | J16: =E16/E17-1 -> 0.026136364 | K16: =F16/F17-1 -> -0.011764706 | M16: E | N16: -0.16859951 | O16: -0.048616987 | P16: 0.071367158 | Q16: 0.19135129 | R16: 0.31133539 | S16: 0.4313195 | T16: 0.55130362 | U16: 0.67128774 | V16: 0.79127187 | W16: 0.91125601 | X16: 1.0312401 | Y16: 1.1512243
A17: 44974 | B17: 28700 | C17: 49650 | D17: 33000 | E17: 44000 | F17: 68000 | G17: =B17/B18-1 -> -0.0034722222 | H17: =C17/C18-1 -> -0.007 | I17: =D17/D18-1 -> 0.012269939 | J17: =E17/E18-1 -> 0.025641026 | K17: =F17/F18-1 -> 0
A18: 44973 | B18: 28800 | C18: 50000 | D18: 32600 | E18: 42900 | F18: 68000 | G18: =B18/B19-1 -> -0.01369863 | H18: =C18/C19-1 -> -0.0099009901 | I18: =D18/D19-1 -> -0.006097561 | J18: =E18/E19-1 -> -0.0057937428 | K18: =F18/F19-1 -> 0.0074074074 | M18: Portfolio Var | N18: {=MMULT(MMULT(TRANSPOSE(N12:N16),$T$5:$X$9),N12:N16)} -> 0.00033433932 | O18: {=MMULT(MMULT(TRANSPOSE(O12:O16),$T$5:$X$9),O12:O16)} -> 0.00024637956 | P18: {=MMULT(MMULT(TRANSPOSE(P12:P16),$T$5:$X$9),P12:P16)} -> 0.00020771198 | Q18: {=MMULT(MMULT(TRANSPOSE(Q12:Q16),$T$5:$X$9),Q12:Q16)} -> 0.00021833654 | R18: {=MMULT(MMULT(TRANSPOSE(R12:R16),$T$5:$X$9),R12:R16)} -> 0.00027825324 | S18: {=MMULT(MMULT(TRANSPOSE(S12:S16),$T$5:$X$9),S12:S16)} -> 0.00038746208 | T18: {=MMULT(MMULT(TRANSPOSE(T12:T16),$T$5:$X$9),T12:T16)} -> 0.00054596306 | U18: {=MMULT(MMULT(TRANSPOSE(U12:U16),$T$5:$X$9),U12:U16)} -> 0.00075375619 | ... Y18: {=MMULT(MMULT(TRANSPOSE(Y12:Y16),$T$5:$X$9),Y12:Y16)} -> 0.0020778501
A19: 44972 | B19: 29200 | C19: 50500 | D19: 32800 | E19: 43150 | F19: 67500 | G19: =B19/B20-1 -> 0.024561404 | H19: =C19/C20-1 -> 0.0059760956 | I19: =D19/D20-1 -> -0.0060606061 | J19: =E19/E20-1 -> -0.0069044879 | K19: =F19/F20-1 -> -0.0088105727 | M19: Portfolio SD | N19: =SQRT(N18) -> 0.018284948 | O19: =SQRT(O18) -> 0.015696482 | P19: =SQRT(P18) -> 0.014412216 | Q19: =SQRT(Q18) -> 0.014776215 | R19: =SQRT(R18) -> 0.016680924 | S19: =SQRT(S18) -> 0.019684056 | T19: =SQRT(T18) -> 0.023365852 | U19: =SQRT(U18) -> 0.027454621 | ... Y19: =SQRT(Y18) -> 0.045583441
A20: 44971 | B20: 28500 | C20: 50200 | D20: 33000 | E20: 43450 | F20: 68100 | G20: =B20/B21-1 -> 0.0035211268 | H20: =C20/C21-1 -> -0.013752456 | I20: =D20/D21-1 -> -0.0060240964 | J20: =E20/E21-1 -> -0.0068571429 | K20: =F20/F21-1 -> -0.020143885 | M20: Portfolio Exp. Return | N20: 0.0005 | O20: 0.001 | P20: 0.0015 | Q20: 0.002 | R20: 0.0025 | S20: 0.003 | T20: 0.0035 | U20: 0.004 | V20: 0.0045 | W20: 0.005 | X20: 0.0055 | Y20: 0.006
A21: 44970 | B21: 28400 | C21: 50900 | D21: 33200 | E21: 43750 | F21: 69500 | G21: =B21/B22-1 -> 0 | H21: =C21/C22-1 -> -0.019267823 | I21: =D21/D22-1 -> 0 | J21: =E21/E22-1 -> -0.01463964 | K21: =F21/F22-1 -> -0.018361582 | M21: Sharpe ratio | N21: =(N20-$V$28)/N19 -> 0.02051092 | O21: =(O20-$V$28)/O19 -> 0.055747592 | P21: =(P20-$V$28)/P19 -> 0.095408026 | Q21: =(Q20-$V$28)/Q19 -> 0.1268959 | R21: =(R20-$V$28)/R19 -> 0.14238067 | S21: =(S20-$V$28)/S19 -> 0.14605938 | T21: =(T20-$V$28)/T19 -> 0.14444331 | U21: =(U20-$V$28)/U19 -> 0.1411435 | ... Y21: =(Y20-$V$28)/Y19 -> 0.12888542
A22: 44967 | B22: 28400 | C22: 51900 | D22: 33200 | E22: 44400 | F22: 70800 | G22: =B22/B23-1 -> -0.013888889 | H22: =C22/C23-1 -> 0.042168675 | I22: =D22/D23-1 -> 0.0060606061 | J22: =E22/E23-1 -> 0.036172695 | K22: =F22/F23-1 -> 0.0042553191
A23: 44966 | B23: 28800 | C23: 49800 | D23: 33000 | E23: 42850 | F23: 70500 | G23: =B23/B24-1 -> 0.0034843206 | H23: =C23/C24-1 -> -0.004 | I23: =D23/D24-1 -> -0.009009009 | J23: =E23/E24-1 -> 0.0046893318 | K23: =F23/F24-1 -> 0.020260492
A24: 44965 | B24: 28700 | C24: 50000 | D24: 33300 | E24: 42650 | F24: 69100 | G24: =B24/B25-1 -> 0.025 | H24: =C24/C25-1 -> 0.002004008 | I24: =D24/D25-1 -> 0.053797468 | J24: =E24/E25-1 -> 0.014268728 | K24: =F24/F25-1 -> -0.007183908 | M24: 5. Optimal risky portfolio | P24: Weight | S24: 6. Combination of Tangent portfolio and RF
A25: 44964 | B25: 28000 | C25: 49900 | D25: 31600 | E25: 42050 | F25: 69600 | G25: =B25/B26-1 -> -0.024390244 | H25: =C25/C26-1 -> -0.002 | I25: =D25/D26-1 -> -0.015576324 | J25: =E25/E26-1 -> -0.0059101655 | K25: =F25/F26-1 -> 0.011627907 | M25: Portfolio Var | N25: {=MMULT(MMULT(TRANSPOSE(Q25:Q29),$T$5:$X$9),Q25:Q29)} -> 0.00038746208 | P25: A | Q25: -0.1764718 | S25: Weight in RF | V25: 0.5
A26: 44963 | B26: 28700 | C26: 50000 | D26: 32100 | E26: 42300 | F26: 68800 | G26: =B26/B27-1 -> 0.014134276 | H26: =C26/C27-1 -> 0.01010101 | I26: =D26/D27-1 -> -0.0031055901 | J26: =E26/E27-1 -> 0 | K26: =F26/F27-1 -> 0.036144578 | M26: Portfolio SD | N26: =SQRT(N25) -> 0.019684056 | P26: B | Q26: 0.060736864 | S26: Portfolio Return with Rf | V26: =V25*V28+(1-V25)*$N$27 -> 0.0015624795
A27: 44960 | B27: 28300 | C27: 49500 | D27: 32200 | E27: 42300 | F27: 66400 | G27: =B27/B28-1 -> 0.014336918 | H27: =C27/C28-1 -> -0.002016129 | I27: =D27/D28-1 -> 0 | J27: =E27/E28-1 -> -0.0011806375 | K27: =F27/F28-1 -> -0.0015037594 | M27: Portfolio Exp. Return | N27: =SUMPRODUCT(Q25:Q29,N4:N8) -> 0.003 | P27: C | Q27: 0.35901442 | S27: Portfolio Standard Deviation with Rf | V27: =(1-V25)*$N$26 -> 0.0098420282
A28: 44959 | B28: 27900 | C28: 49600 | D28: 32200 | E28: 42350 | F28: 66500 | G28: =B28/B29-1 -> -0.014134276 | H28: =C28/C29-1 -> 0.002020202 | I28: =D28/D29-1 -> -0.021276596 | J28: =E28/E29-1 -> -0.010514019 | K28: =F28/F29-1 -> 0.013719512 | M28: Sharpe ratio | N28: =(N27-V28)/N26 -> 0.14605938 | P28: D | Q28: 0.32540102 | S28: Return/ Daily | V28: =V29/365 -> 0.0001249589
A29: 44958 | B29: 28300 | C29: 49500 | D29: 32900 | E29: 42800 | F29: 65600 | G29: =B29/B30-1 -> 0.080152672 | H29: =C29/C30-1 -> 0.053191489 | I29: =D29/D30-1 -> 0.024922118 | J29: =E29/E30-1 -> 0.0023419204 | K29: =F29/F30-1 -> 0.021806854 | P29: E | Q29: 0.4313195 | S29: Annual Return of Risk-free Rate | V29: 0.04561
A30: 44957 | B30: 26200 | C30: 47000 | D30: 32100 | E30: 42700 | F30: 64200 | G30: =B30/B31-1 -> -0.050724638 | H30: =C30/C31-1 -> -0.0084388186 | I30: =D30/D31-1 -> -0.021341463 | J30: =E30/E31-1 -> -0.016129032 | K30: =F30/F31-1 -> -0.048888889 | P30: Sum | Q30: =SUM(Q25:Q29) -> 1
A31: 44956 | B31: 27600 | C31: 47400 | D31: 32800 | E31: 43400 | F31: 67500 | G31: =B31/B32-1 -> -0.0071942446 | H31: =C31/C32-1 -> -0.0125 | I31: =D31/D32-1 -> 0 | J31: =E31/E32-1 -> -0.013636364 | K31: =F31/F32-1 -> -0.018895349
A32: 44953 | B32: 27800 | C32: 48000 | D32: 32800 | E32: 44000 | F32: 68800 | G32: =B32/B33-1 -> -0.014184397 | H32: =C32/C33-1 -> 0 | I32: =D32/D33-1 -> -0.0030395137 | J32: =E32/E33-1 -> 0.011494253 | K32: =F32/F33-1 -> -0.025495751 | M32: 7. Capital allocation line
A33: 44945 | B33: 28200 | C33: 48000 | D33: 32900 | E33: 43500 | F33: 70600 | G33: =B33/B34-1 -> 0.0035587189 | H33: =C33/C34-1 -> 0.010526316 | I33: =D33/D34-1 -> 0.006116208 | J33: =E33/E34-1 -> 0.01635514 | K33: =F33/F34-1 -> 0.023188406 | M33: Weight of RF | N33: Portfolio SD | O33: Portfolio Exp. Return
A34: 44944 | B34: 28100 | C34: 47500 | D34: 32700 | E34: 42800 | F34: 69000 | G34: =B34/B35-1 -> 0.040740741 | H34: =C34/C35-1 -> -0.0031479538 | I34: =D34/D35-1 -> -0.015060241 | J34: =E34/E35-1 -> -0.011547344 | K34: =F34/F35-1 -> -0.0086206897 | N34: =V27 -> 0.0098420282 | O34: =V26 -> 0.0015624795
A35: 44943 | B35: 27000 | C35: 47650 | D35: 33200 | E35: 43300 | F35: 69600 | G35: =B35/B36-1 -> -0.042553191 | H35: =C35/C36-1 -> -0.0093555094 | I35: =D35/D36-1 -> -0.017751479 | J35: =E35/E36-1 -> -0.014789534 | K35: =F35/F36-1 -> -0.030640669 | M35: 1 | N35: 0 | O35: 0.0001249589
A36: 44942 | B36: 28200 | C36: 48100 | D36: 33800 | E36: 43950 | F36: 71800 | G36: =B36/B37-1 -> 0 | H36: =C36/C37-1 -> 0.0083857442 | I36: =D36/D37-1 -> 0.015015015 | J36: =E36/E37-1 -> 0.0022805017 | K36: =F36/F37-1 -> 0.021337127 | M36: 0.9 | N36: 0.0019684056 | O36: 0.00041246302
A37: 44939 | B37: 28200 | C37: 47700 | D37: 33300 | E37: 43850 | F37: 70300 | G37: =B37/B38-1 -> -0.0070422535 | H37: =C37/C38-1 -> 0.0063291139 | I37: =D37/D38-1 -> 0.0060422961 | J37: =E37/E38-1 -> 0.012702079 | K37: =F37/F38-1 -> -0.0098591549 | M37: 0.8 | N37: 0.0039368113 | O37: 0.00069996713
A38: 44938 | B38: 28400 | C38: 47400 | D38: 33100 | E38: 43300 | F38: 71000 | G38: =B38/B39-1 -> 0.063670412 | H38: =C38/C39-1 -> 0.0053022269 | I38: =D38/D39-1 -> 0.012232416 | J38: =E38/E39-1 -> -0.022573363 | K38: =F38/F39-1 -> 0.021582734 | M38: 0.7 | N38: 0.0059052169 | O38: 0.00098747124
A39: 44937 | B39: 26700 | C39: 47150 | D39: 32700 | E39: 44300 | F39: 69500 | G39: =B39/B40-1 -> -0.0074349442 | H39: =C39/C40-1 -> 0.0053304904 | I39: =D39/D40-1 -> -0.026785714 | J39: =E39/E40-1 -> -0.015555556 | K39: =F39/F40-1 -> 0.069230769 | M39: 0.6 | N39: 0.0078736226 | O39: 0.0012749753
A40: 44936 | B40: 26900 | C40: 46900 | D40: 33600 | E40: 45000 | F40: 65000 | G40: =B40/B41-1 -> 0.054901961 | H40: =C40/C41-1 -> 0.0021367521 | I40: =D40/D41-1 -> -0.01754386 | J40: =E40/E41-1 -> -0.010989011 | K40: =F40/F41-1 -> -0.0030674847 | M40: 0.5 | N40: 0.0098420282 | O40: 0.0015624795
...
