Workbook

Sheet Giao dich (Transactions)
A1: SỔ GIAO DỊCH — DANH MỤC 2 (Trading Ledger — Portfolio 2)
A2: Vốn gốc / Initial capital: 60.000.000 đ | Đơn vị: VND | Cập nhật đến 16/09/2026 | Nguồn: data/so_giao_dich.json
A4: STT (No.) | B4: Ngày (Date) | C4: Loại GD (Type) | D4: Mã CK (Ticker) | E4: Khối lượng (Qty) | F4: Giá khớp (Price) | G4: Giá trị GD (Trade Value) | H4: Phí dịch vụ (Service Fee) | I4: Thuế TNCN (Tax) | J4: Dòng tiền ròng (Net Cash Flow) | K4: Dư tiền mặt sau GD (Cash Balance) | L4: Lãi/lỗ gộp (Gross P&L) | M4: Lãi/lỗ ròng (Net P&L) | N4: Căn cứ (Basis/Rule) | O4: Ghi chú (Note) | P4: Ngày ghi sổ gốc (Raw date field)
A5: 1 | B5: truoc 17/08 | C5: MUA | D5: MSB | E5: 700 | F5: 16000 | G5: 11200000 | H5: 8960 | I5: 0 | J5: -11208960 | K5: 48791040 | N5: khung cu | O5: ke thua tu khung cu | P5: truoc 17/08
A6: 2 | B6: truoc 17/08 | C6: MUA | D6: VNM | E6: 200 | F6: 62500 | G6: 12500000 | H6: 10000 | I6: 0 | J6: -12510000 | K6: 36281040 | N6: khung cu | O6: ke thua, gia von suy ra | P6: truoc 17/08
A7: 3 | B7: truoc 17/08 | C7: MUA | D7: BAF | E7: 100 | F7: 32150 | G7: 3215000 | H7: 2572 | I7: 0 | J7: -3217572 | K7: 33063468 | N7: khung cu | O7: ke thua, gia von suy ra | P7: truoc 17/08
A8: 4 | B8: 17-19/08 | C8: MUA | D8: BSR | E8: 200 | F8: 27000 | G8: 5400000 | H8: 4320 | I8: 0 | J8: -5404320 | K8: 27659148 | N8: bang lenh 17/08 | O8: ke hoach 26.000, khop cao hon 1.000 | P8: 17-19/08
A9: 5 | B9: 17-19/08 | C9: MUA | D9: GMD | E9: 100 | F9: 78800 | G9: 7880000 | H9: 6304 | I9: 0 | J9: -7886304 | K9: 19772844 | N9: bang lenh 17/08 | O9: khop dung ke hoach | P9: 17-19/08
A10: 6 | B10: 17-19/08 | C10: MUA | D10: LPB | E10: 100 | F10: 50800 | G10: 5080000 | H10: 4064 | I10: 0 | J10: -5084064 | K10: 14688780 | N10: bang lenh 17/08 | O10: ke hoach 50.900 | P10: 17-19/08
A11: 7 | B11: 17-19/08 | C11: MUA | D11: STB | E11: 100 | F11: 74200 | G11: 7420000 | H11: 5936 | I11: 0 | J11: -7425936 | K11: 7262844 | N11: bang lenh 17/08 | O11: khop dung ke hoach | P11: 17-19/08
A12: 8 | B12: 17-19/08 | C12: MUA | D12: VHM | E12: 100 | F12: 69000 | G12: 6900000 | H12: 5520 | I12: 0 | J12: -6905520 | K12: 357324 | N12: bang lenh 17/08 | O12: ke hoach 68.200, khop cao hon 800 | P12: 17-19/08
A13: 9 | B13: 2026-08-19 | C13: BAN | D13: VNM | E13: 200 | F13: 62000 | G13: 12400000 | H13: 9920 | I13: 12400 | J13: 12377680 | K13: 12735004 | L13: -100000 | M13: -132320 | N13: quy tac thoat 1 | O13: MA50 < MA200 | P13: 2026-08-19
A14: 10 | B14: 2026-08-19 | C14: BAN | D14: BAF | E14: 100 | F14: 31500 | G14: 3150000 | H14: 2520 | I14: 3150 | J14: 3144330 | K14: 15879334 | L14: -65000 | M14: -73242 | N14: quy tac thoat 2 | O14: RS 12T thua VNINDEX | P14: 2026-08-19
A15: 11 | B15: 2026-09-03 | C15: MUA | D15: DHC | E15: 200 | F15: 36600 | G15: 7320000 | H15: 5856 | I15: 0 | J15: -7325856 | K15: 8553478 | N15: ky soat 09 | O15: ke hoach 36.900, khop thap hon 300 | P15: 2026-09-03
A16: 12 | B16: 2026-09-03 | C16: BAN | D16: GMD | E16: 100 | F16: 78100 | G16: 7810000 | H16: 6248 | I16: 7810 | J16: 7795942 | K16: 16349420 | L16: -70000 | M16: -90362 | N16: quy tac thoat 3 | O16: rot khoi top 40% | P16: 2026-09-03
A17: 13 | B17: 2026-09-03 | C17: BAN | D17: LPB | E17: 100 | F17: 49050 | G17: 4905000 | H17: 3924 | I17: 4905 | J17: 4896171 | K17: 21245591 | L17: -175000 | M17: -187893 | N17: quy tac thoat 3 | O17: rot khoi top 40% | P17: 2026-09-03
A18: 14 | B18: 2026-09-07 | C18: BAN | D18: VHM | E18: 50 | F18: 77700 | G18: 3885000 | H18: 3108 | I18: 3885 | J18: 3878007 | K18: 25123598 | L18: 435000 | M18: 425247 | N18: LENH NGOAI LUAT #1 | O18: chot lai mot phan | P18: 2026-09-07
A19: 15 | B19: 2026-09-14 | C19: BAN | D19: STB | E19: 100 | F19: 76900 | G19: 7690000 | H19: 6152 | I19: 7690 | J19: 7676158 | K19: 32799756 | L19: 270000 | M19: 250222 | N19: quy tac thoat 4 | O19: luan diem gay, phieu 1/6 | P19: 2026-09-14
A20: 16 | B20: 2026-09-16 | C20: BAN | D20: BSR | E20: 100 | F20: 31300 | G20: 3130000 | H20: 2504 | I20: 3130 | J20: 3124366 | K20: 35924122 | L20: 430000 | M20: 422206 | N20: QUY_TAC_5 (ban theo cam quan thi truong cua quy) | O20: Ban 50% vi the (100/200 CP) - dung tran 50%. GHI SAU KHI DA KHOP, khong dung thu tu QUY_TAC_5 doi hoi (ghi TRUOC lenh) - le sai quy trinh, ghi lai trung thuc. cam_quan: lo ngai chung ve thi truong/nhom nganh dau khi, khong rieng ve ban than BSR. Chi tiet: LENH_QUY_TAC_5 so 1 trong lt_config.py. | P20: 2026-09-16
A21: TỔNG (Total) | G21: 109885000 | H21: 87908 | I21: 42970

Sheet Phan bo hien tai (Allocation)
A1: PHÂN BỔ DANH MỤC HIỆN TẠI — DANH MỤC 2 (Current Portfolio Allocation)
A2: Tại ngày 16/09/2026 (giá MIXED: BSR theo giá khớp 16/09, MSB/VHM/DHC theo giá 15/09) | NAV dựng lại: 60,888,122 đ | Nguồn: data/so_giao_dich.json + lt_config_backup_20260916.py
A4: Mã CK (Ticker) | B4: Ngành (Sector) | C4: Khối lượng (Qty) | D4: Giá vốn BQ (Avg Cost) | E4: Giá trị vốn (Cost Value) | F4: Giá hiện tại (Market Price) | G4: Giá trị thị trường (Market Value) | H4: % NAV (Weight) | I4: Lãi/lỗ gộp (Gross P&L) | J4: Lãi/lỗ ròng (Net P&L) | K4: % Lãi/lỗ ròng (Net Return) | L4: Ghi chú (Note)
A5: BSR | B5: Dau khi | C5: 100 | D5: 27000 | E5: 2700000 | F5: 31300 | G5: 3130000 | H5: 0.051405757 | I5: 430000 | J5: 427840 | K5: 0.15845926 | L5: Con 100/200 CP sau khi ban 100 theo QUY_TAC_5 ngay 16/09. Gia moi nhat 16/09, khac ngay voi ba vi the con lai (van 15/09) - can dinh gia lai dong bo o ky soat ke tiep.
A6: DHC | B6: Giay | C6: 200 | D6: 36600 | E6: 7320000 | F6: 37300 | G6: 7460000 | H6: 0.12251979 | I6: 140000 | J6: 134144 | K6: 0.018325683
A7: MSB | B7: Ngan hang | C7: 840 | D7: 13333 | E7: 11200000 | F7: 12850 | G7: 10794000 | H7: 0.17727596 | I7: -406000 | J7: -414960 | K7: -0.03705
A8: VHM | B8: Bat dong san | C8: 50 | D8: 69000 | E8: 3450000 | F8: 71600 | G8: 3580000 | H8: 0.058796361 | I8: 130000 | J8: 127240 | K8: 0.036881159
A9: TIỀN MẶT (Cash) | G9: 35924122 | H9: 0.59000214
A10: TỔNG NAV (Total NAV) | E10: 24964000 | G10: 60888122 | H10: 1
A12: PHÂN BỔ THEO NGÀNH (Sector Allocation)
A13: Ngành (Sector) | B13: Giá trị (Value) | C13: % NAV | D13: Trần ngành DM2 (Sector cap) | E13: Còn dư (Headroom)
A14: Dau khi | B14: 3130000 | C14: 0.051405757 | D14: 0.4 | E14: 0.34859424
A15: Giay | B15: 7460000 | C15: 0.12251979 | D15: 0.4 | E15: 0.27748021
A16: Ngan hang | B16: 10794000 | C16: 0.17727596 | D16: 0.4 | E16: 0.22272404
A17: Bat dong san | B17: 3580000 | C17: 0.058796361 | D17: 0.4 | E17: 0.34120364

Sheet Tham so phan bo (Constraints)
A1: THAM SỐ & RÀNG BUỘC PHÂN BỔ — DANH MỤC 2 (Allocation Parameters & Constraints)
A2: Nguồn: data/lt_config_backup_20260916.py — PORTFOLIOS['DM2'], LOC, NGANH
A4: Tham số (Parameter) | B4: Giá trị (Value)
A5: Tên danh mục (Portfolio name) | B5: Danh mục 2 — tài khoản dự thi (Contest account)
A6: Vốn ban đầu (Initial capital) | B6: 60000000
A7: NAV hiện tại, dựng lại (Current NAV, rebuilt) | B7: 60888122
A8: Số vị thế mục tiêu (Target # positions) | B8: 8
A9: Số vị thế hiện tại (Current # positions) | B9: 4
A10: Trần 1 mã / NAV (Single-name cap) | B10: 0.2
A11: Trần 1 ngành / NAV (Sector cap) | B11: 0.4
A12: Ticket tối thiểu / lệnh (Min ticket size) | B12: 5000000
A13: Thanh khoản tối thiểu (Min 20-day avg liquidity) | B13: 10000000000
A14: Bộ lọc cứng (Hard filters) | B14: Close > MA200; MA50 > MA200; RS 12T > VNINDEX; ATR ≤ 6,0%
A15: Phương pháp xếp hạng (Ranking method) | B15: RS đa khung: 40% RS252(skip21) + 30% RS126 + 20% RS63 + 10% Trend R²
A16: Phương pháp phân bổ (Sizing method) | B16: Risk parity xấp xỉ 1/ATR, có trần mã & trần ngành
A17: Tần suất soát danh mục (Rebalance frequency) | B17: Đầu mỗi tháng + kỳ bổ sung 21/09/2026 (giai đoạn 2 cuộc thi)
A18: Quy tắc bán tùy nghi (Discretionary sell rule) | B18: QUY_TAC_5: tối đa 50% vị thế/lần, hiệu lực tới kỳ soát kế tiếp, phải ghi trước khi đặt lệnh

Sheet Tong ket (Summary)
A1: TÓM TẮT HIỆU QUẢ ĐẦU TƯ — DANH MỤC 2 (Performance Summary)
A2: Nguồn: data/so_giao_dich.json — tong_ket
A4: Chỉ tiêu (Metric) | B4: Giá trị (Value)
A5: Số lượt lệnh (Total orders) | B5: 16
A6: Số lệnh mua (Buy orders) | B6: 9
A7: Số lệnh bán (Sell orders) | B7: 7
A8: Tổng giá trị giao dịch (Total trade value) | B8: 109885000
A9: Tổng phí dịch vụ (Total service fee) | B9: 87908
A10: — Phí mua (Buy fee) | B10: 53532
A11: — Phí bán (Sell fee) | B11: 34376
A12: Tổng thuế TNCN (Total tax on sells) | B12: 42970
A13: Tổng chi phí giao dịch (Total transaction cost) | B13: 130878
A14: Chi phí / vốn gốc (Cost as % of capital) | B14: 0.2181
A15: Lãi/lỗ đã thực hiện, gộp (Realized P&L, gross) | B15: 725000
A16: Lãi/lỗ đã thực hiện, ròng (Realized P&L, net) | B16: 613858
... A22: Tổng lợi nhuận ròng / vốn gốc (Total net return) | B22: 0.014802033
A24: Ghi chú đối chiếu (Reconciliation note):
A25: NAV dựng lại 60.888.122 đ dùng giá MIXED NGÀY (BSR theo giá khớp bán 16/09, ba mã còn lại theo giá 15/09) nên chưa so sánh trực tiếp được với sao kê 15/09 (60.444.027 đ, lệch 271 đ / 0,00045%, nghi ngờ do lãi tiền gửi hoặc làm tròn CTCK). Cần sao kê mới đồng ngày để đóng lại chênh lệch.

Sheet Soat DM2 16.09
A1: SOÁT DANH MỤC & CHUẨN BỊ TÁI CÂN BẰNG — DANH MỤC 2 (Portfolio Rebalance Review)
A2: Tại ngày 16/09/2026 | Nguồn: chính sổ tính này (Giao dich / Phan bo hien tai / Tham so phan bo / Tong ket / Bieu phi / Su kien). Không có connector danh mục (Orion / Addepar / Tamarac) hay BlackRock Advisor Center trong phiên — đây là chỗ sẽ gọi ra hệ thống đó khi connector được dựng.
A3: BẢN NHÁP ĐỂ NGƯỜI RA QUYẾT ĐỊNH CÂN NHẮC — không phải khuyến nghị đầu tư, không phải lệnh đã đặt.
A5: 1. CỔNG KIỂM TRA DỮ LIỆU (Data-sanity gate) — Kết luận: FLAGS (tiếp tục kèm cảnh báo), không BLOCKING
A6: Chốt (Check) | B6: Phát hiện (Finding) | C6: Ảnh hưởng tới (Contaminates) | D6: Mức
A7: Đối chiếu nội bộ | B7: Giá trị CK 24.964.000 + tiền 35.924.122 = 60.888.122 đ, trùng NAV dựng lại; các % NAV cộng đủ 100% | C7: — (đã sạch) | D7: PASS
A8: Đối chiếu với sao kê | B8: Ghi chú trên sheet Tong ket nói lệch 271 đ / 0,00045%, nhưng hai số NAV nêu trên sheet lệch 444.095 đ (0,73%). Không dựng lại được số 271 đ từ dữ liệu có sẵn. | C8: Độ tin của mọi % NAV khi so với sao kê; mẫu số NAV của bảng lệch chuẩn | D8: FLAG
A9: Tổng cộng (Aggregation) | B9: Ô tổng cột "Giá trị vốn" trên sheet Phan bo hien tai ghi 24.964.000 đ — đó là giá trị THỊ TRƯỜNG. Tổng giá vốn thực của 4 vị thế = 24.670.000 đ. | C9: Mọi phép tính lãi/lỗ theo giá vốn, tỷ suất trên vốn | D9: FLAG
A10: Đầy đủ (Completeness) | B10: (a) Phí lưu ký 819 đ không nằm trong "Tổng chi phí giao dịch 130.878 đ". (b) 140 CP thưởng MSB chưa xác nhận về TK (≈1,8 tr, 3% NAV) — nếu chưa về, lệnh bán MSB chỉ khớp 700 CP. | C10: Tổng chi phí thực; khối lượng MSB khả bán trong bảng lệnh | D10: FLAG
A11: Cũ/mới (Staleness) | B11: BSR định giá theo giá khớp 16/09; DHC, MSB, VHM theo giá 15/09 — không đồng ngày | C11: So sánh % NAV giữa các vị thế; giá trị lệch tính bằng tiền | D11: FLAG
A12: Thời gian (Temporal) | B12: Không có vị thế nào có ngày định giá trước ngày mua | C12: — | D12: PASS
A13: Độ lớn (Magnitude) | B13: Lãi/lỗ lớn nhất là BSR +15,8% ròng — hợp lý với thời gian nắm giữ; không có mức bất thường | C13: — | D13: PASS
A14: Trùng lặp (Duplication) | B14: Mỗi mã xuất hiện một lần; không có tài khoản ngoài hệ thống được khai báo (chưa xác nhận — xem câu hỏi ở phần 5) | C14: — | D14: PASS
A16: 2. BẢNG LỆCH CHUẨN — mốc so sánh: risk parity xấp xỉ 1/ATR, có trần mã, trên 8 vị thế mục tiêu
A17: Tiền mặt mục tiêu % NAV (input) | B17: 0
A18: NAV làm mẫu số (đ) | B18: ='Tham so phan bo (Constraints)'!B7 -> 60888122
A19: Trần 1 mã / NAV | B19: ='Tham so phan bo (Constraints)'!B10 -> 0.2
A20: Mã | B20: Ngành | C20: KL hiện tại | D20: Giá hiện tại | E20: Giá trị TT (đ) | F20: % NAV hiện tại | G20: ATR % (input) | H20: 1/ATR | I20: Target thô % | J20: Target sau trần % | K20: Lệch (hiện tại − target) | L20: Giá trị lệch (đ) | M20: Ghi chú
A21: ='Phan bo hien tai (Allocation)'!A5 -> BSR | B21: ='Phan bo hien tai (Allocation)'!B5 -> Dau khi | C21: ='Phan bo hien tai (Allocation)'!C5 -> 100 | D21: ='Phan bo hien tai (Allocation)'!F5 -> 31300 | E21: =C21*D21 -> 3130000 | F21: =E21/$B$18 -> 0.051405757 | H21: =IFERROR(1/G21,"") | I21: =IFERROR((1-$B$17)*H21/SUM($H$21:$H$28),"") | J21: =IF(N(I21)=0,"",MIN(I21,$B$19)) | K21: =IFERROR(F21-J21,"") | L21: =IFERROR(K21*$B$18,"") | M21: Đã bán 100/200 CP theo QUY_TAC_5 ngày 16/09. Quy tắc có hiệu lực tới kỳ soát kế tiếp — không mua lại trong kỳ này. Giá 16/09, lệch ngày với ba mã còn lại.
A22: ='Phan bo hien tai (Allocation)'!A6 -> DHC | B22: ='Phan bo hien tai (Allocation)'!B6 -> Giay | C22: ='Phan bo hien tai (Allocation)'!C6 -> 200 | D22: ='Phan bo hien tai (Allocation)'!F6 -> 37300 | E22: =C22*D22 -> 7460000 | F22: =E22/$B$18 -> 0.12251979 | H22: =IFERROR(1/G22,"") | I22: =IFERROR((1-$B$17)*H22/SUM($H$21:$H$28),"") | J22: =IF(N(I22)=0,"",MIN(I22,$B$19)) | K22: =IFERROR(F22-J22,"") | L22: =IFERROR(K22*$B$18,"") | M22: Mua 03/09, lãi ròng +1,8%. Giá 15/09.
A23: ='Phan bo hien tai (Allocation)'!A7 -> MSB | B23: ='Phan bo hien tai (Allocation)'!B7 -> Ngan hang | C23: ='Phan bo hien tai (Allocation)'!C7 -> 840 | D23: ='Phan bo hien tai (Allocation)'!F7 -> 12850 | E23: =C23*D23 -> 10794000 | F23: =E23/$B$18 -> 0.17727596 | H23: =IFERROR(1/G23,"") | I23: =IFERROR((1-$B$17)*H23/SUM($H$21:$H$28),"") | J23: =IF(N(I23)=0,"",MIN(I23,$B$19)) | K23: =IFERROR(F23-J23,"") | L23: =IFERROR(K23*$B$18,"") | M23: Vị thế lớn nhất (sát trần 20% hơn cả), lỗ ròng −3,7%. Trong 840 CP có 140 CP thưởng CHƯA XÁC NHẬN về TK — khối lượng khả bán có thể chỉ 700 CP.
A24: ='Phan bo hien tai (Allocation)'!A8 -> VHM | B24: ='Phan bo hien tai (Allocation)'!B8 -> Bat dong san | C24: ='Phan bo hien tai (Allocation)'!C8 -> 50 | D24: ='Phan bo hien tai (Allocation)'!F8 -> 71600 | E24: =C24*D24 -> 3580000 | F24: =E24/$B$18 -> 0.058796361 | H24: =IFERROR(1/G24,"") | I24: =IFERROR((1-$B$17)*H24/SUM($H$21:$H$28),"") | J24: =IF(N(I24)=0,"",MIN(I24,$B$19)) | K24: =IFERROR(F24-J24,"") | L24: =IFERROR(K24*$B$18,"") | M24: Còn 50/100 CP sau LỆNH NGOÀI LUẬT #1 (07/09, yêu cầu người góp vốn). Giá 15/09.
A25: Ứng viên 1 (input) | E25: =C25*D25 -> 0 | F25: =E25/$B$18 -> 0 | H25: =IFERROR(1/G25,"") | I25: =IFERROR((1-$B$17)*H25/SUM($H$21:$H$28),"") | J25: =IF(N(I25)=0,"",MIN(I25,$B$19)) | K25: =IFERROR(F25-J25,"") | L25: =IFERROR(K25*$B$18,"") | M25: Slot trống. Cần mã qua được bộ lọc cứng (Close>MA200; MA50>MA200; RS 12T>VNINDEX; ATR≤6,0%) và thanh khoản ≥10 tỷ/20 phiên — số liệu xếp hạng RS không có trong sổ tính này.
A26: Ứng viên 2 (input) | E26: =C26*D26 -> 0 | F26: =E26/$B$18 -> 0 | H26: =IFERROR(1/G26,"") | I26: =IFERROR((1-$B$17)*H26/SUM($H$21:$H$28),"") | J26: =IF(N(I26)=0,"",MIN(I26,$B$19)) | K26: =IFERROR(F26-J26,"") | L26: =IFERROR(K26*$B$18,"") | M26: Slot trống. Cần mã qua được bộ lọc cứng (Close>MA200; MA50>MA200; RS 12T>VNINDEX; ATR≤6,0%) và thanh khoản ≥10 tỷ/20 phiên — số liệu xếp hạng RS không có trong sổ tính này.
A27: Ứng viên 3 (input) | E27: =C27*D27 -> 0 | F27: =E27/$B$18 -> 0 | H27: =IFERROR(1/G27,"") | I27: =IFERROR((1-$B$17)*H27/SUM($H$21:$H$28),"") | J27: =IF(N(I27)=0,"",MIN(I27,$B$19)) | K27: =IFERROR(F27-J27,"") | L27: =IFERROR(K27*$B$18,"") | M27: Slot trống. Cần mã qua được bộ lọc cứng (Close>MA200; MA50>MA200; RS 12T>VNINDEX; ATR≤6,0%) và thanh khoản ≥10 tỷ/20 phiên — số liệu xếp hạng RS không có trong sổ tính này.
A28: Ứng viên 4 (input) | E28: =C28*D28 -> 0 | F28: =E28/$B$18 -> 0 | H28: =IFERROR(1/G28,"") | I28: =IFERROR((1-$B$17)*H28/SUM($H$21:$H$28),"") | J28: =IF(N(I28)=0,"",MIN(I28,$B$19)) | K28: =IFERROR(F28-J28,"") | L28: =IFERROR(K28*$B$18,"") | M28: Slot trống. Cần mã qua được bộ lọc cứng (Close>MA200; MA50>MA200; RS 12T>VNINDEX; ATR≤6,0%) và thanh khoản ≥10 tỷ/20 phiên — số liệu xếp hạng RS không có trong sổ tính này.
A29: TIỀN MẶT (Cash) | E29: ='Phan bo hien tai (Allocation)'!G9 -> 35924122 | F29: =E29/$B$18 -> 0.59000214 | J29: =$B$17 -> 0 | K29: =F29-J29 -> 0.59000214 | L29: =K29*$B$18 -> 35924122 | M29: Lệch lớn nhất của danh mục. 4/8 slot trống nên tiền đọng.
A30: TỔNG | E30: =SUM(E21:E29) -> 60888122 | F30: =SUM(F21:F29) -> 1 | J30: =SUM(J21:J29) -> 0 | K30: =F30-J30 -> 1 | L30: =K30*$B$18 -> 60888122 | M30: Cột J chỉ cộng đủ 100% khi đã nhập ATR cho cả 8 mã. Nếu một mã bị cắt theo trần 20%, phần vượt KHÔNG được phân bổ lại tự động — cần tăng thủ công.
A32: 3. TIỀN KHẢ DỤNG, TRẦN NGÀNH & RÀNG BUỘC THỰC THI
A33: Tiền mặt hiện có (đ) | B33: =E29 -> 35924122
A34: Tiền muốn giữ lại (input, đ) | B34: 0
A35: Tiền khả dụng để mua (đ) | B35: =B33-B34 -> 35924122
A36: Ticket tối thiểu / lệnh (đ) | B36: ='Tham so phan bo (Constraints)'!B12 -> 5000000
A37: Số slot còn trống (mục tiêu − hiện tại) | B37: ='Tham so phan bo (Constraints)'!B8-'Tham so phan bo (Constraints)'!B9 -> 4
A38: Ticket bình quân nếu lấp đủ slot (đ) | B38: =IFERROR(B35/B37,"") -> 8981030.5
A39: Số lệnh tối đa theo ticket tối thiểu | B39: =ROUNDDOWN(B35/B36,0) -> 7
A40: Trần 1 ngành / NAV | B40: ='Tham so phan bo (Constraints)'!B11 -> 0.4
A41: Ngành | B41: % NAV hiện tại | C41: Còn dư (% NAV) | D41: Còn dư (đ)
A42: ='Phan bo hien tai (Allocation)'!A14 -> Dau khi | B42: ='Phan bo hien tai (Allocation)'!B14/$B$18 -> 0.051405757 | C42: =$B$40-B42 -> 0.34859424 | D42: =C42*$B$18 -> 21225249
A43: ='Phan bo hien tai (Allocation)'!A15 -> Giay | B43: ='Phan bo hien tai (Allocation)'!B15/$B$18 -> 0.12251979 | C43: =$B$40-B43 -> 0.27748021 | D43: =C43*$B$18 -> 16895249
...

Sheet Bien ban can cu
A1: BIÊN BẢN CĂN CỨ TÁI CÂN BẰNG (Rebalance Rationale Memo)
A2: Danh mục: Danh mục 2 — tài khoản dự thi | Ngày: 16/09/2026 | Người quản lý: [điền] | Soạn bởi: Claude (bản nháp — người quản lý rà soát)
A4: 1. MỤC TIÊU & THAM CHIẾU CHÍNH SÁCH
A5: Không có IPS rời. Văn bản chính sách là sheet "Tham so phan bo (Constraints)", dẫn từ lt_config_backup_20260916.py: 8 vị thế mục tiêu; trần 20%/mã; trần 40%/ngành; ticket tối thiểu 5.000.000 đ; thanh khoản tối thiểu 10 tỷ đ/20 phiên; bộ lọc cứng Close>MA200, MA50>MA200, RS 12T>VNINDEX, ATR≤6,0%; sizing risk parity xấp xỉ 1/ATR; tần suất soát đầu mỗi tháng + kỳ bổ sung 21/09/2026.
A6: Chính sách KHÔNG quy định: tỷ trọng mục tiêu điểm cho từng mã, biên dung sai (band) quanh mục tiêu, mức tiền mặt mục tiêu, và ngày rà soát lại chính sách. Bảng lệch chuẩn vì vậy dụng target từ 1/ATR theo phương pháp sizing đã ghi, do người quản lý chọn làm mốc — không phải một mục tiêu có sẵn trong hồ sơ.
A8: 2. LÝ DO PHÁT SINH RÀ SOÁT
A9: [x] Lệch phân bổ: 4/8 vị thế, tiền mặt 59,0% NAV (35.924.122 đ) — đây là độ lệch lớn nhất, không phải lệch giữa các ngành. Nguyên nhân: 7 lệnh bán từ 19/08 đến 16/09 (4 theo quy tắc thoát, 1 lệnh ngoài luật theo yêu cầu người góp vốn, 1 theo QUY_TAC_5) mà chưa tái giải ngân.
A10: [x] Tiền cần giải ngân: room mua ~30 tr nếu lấp đủ 4 slot ở mức ticket tối thiểu; 7 lệnh nếu chia theo ticket tối thiểu.
A11: [ ] Trần bị vi phạm: KHÔNG. Trần mã 20% — sát nhất là MSB 17,7%. Trần ngành 40% — cao nhất là Ngân hàng 17,7%. Không có vị thế nào vượt trần.
A12: [ ] Thu đầu tư lỗ để giảm thuế: không áp dụng — thuế CK cá nhân Việt Nam 0,1% tính trên giá trị bán bất kể lãi hay lỗ, nên bán lỗ không tạo lợi ích thuế.
A14: 3. CÁC ĐIỀU CHỈNH & CĂN CỨ TẮNG CÁI
A15: Bảng lệnh chi tiết nằm ở sheet "Soat DM2 16.09" phần 4 (A48:K58) và tự tính lại khi nhập ATR. Trạng thái hiện tại: CHƯA có khối lượng nào được đề xuất, vì thiếu ATR và thiếu danh sách ứng viên qua bộ lọc. Căn cứ từng mã đã ghi ở cột I của bảng đó.
... A51: Lưu trữ theo chính sách hồ sơ của chính bạn. Bản nháp do Claude soạn, không phải khuyến nghị đầu tư, không phải kết luận về tính phù hợp.

Sheet Bieu phi (Fee schedule)
A1: BIỂU PHÍ ÁP DỤNG — DANH MỤC 2 (Fee Schedule)
A2: Sửa 15/09/2026, áp dụng hồi tố cho toàn bộ lịch sử từ vốn gốc | Nguồn: data/so_giao_dich.json
A4: Loại phí (Fee type) | B4: Biểu phí ĐÚNG hiện hành (Current, correct) | C4: Biểu phí CŨ đã bỏ (Old, deprecated)
A5: Phí dịch vụ (2 chiều mua & bán) (Service fee, both ways) | B5: 0.0008 | C5: 0.0015
A6: Thuế TNCN (chỉ khi bán) (Tax, sell only) | B6: 0.001
A7: Phí lưu ký VSD (theo thời gian nắm giữ) (Custody fee, per share/month) | B7: 0.3 đ/CP/tháng | C7: —
A9: So sánh tổng chi phí 15 lệnh đầu (Cost comparison, first 15 orders):
A10: Chi phí theo biểu phí đúng (Cost, correct schedule) | B10: 130878
A11: Chi phí theo biểu phí cũ (Cost, old schedule) | B11: 199973
A12: Tiết kiệm được (Savings) | B12: 74728
A14: PHÍ LƯU KÝ THEO THÁNG (Custody fee by month)
A15: Tháng (Month) | B15: Số CP cuối tháng (Shares held EOM) | C15: Phí (Fee)
A16: 08/2026 | B16: 1440 | C16: 432
A17: 09/2026 | B17: 1290 | C17: 387
A18: Cộng (Total) | C18: 819

Sheet Su kien & ngoai le (Events)
A1: SỰ KIỆN ĐẶC BIỆT & LỆNH NGOÀI LUẬT — DANH MỤC 2 (Corporate Actions & Discretionary Exceptions)
A2: Nguồn: data/so_giao_dich.json + data/lt_config_backup_20260916.py
A4: 1. SỰ KIỆN CỔ TỨC / QUYỀN (Corporate Actions)
A5: Ngày (Date) | B5: Mã (Ticker) | C5: Sự kiện (Event) | D5: Trước (Before) | E5: Sau (After)
A6: 2026-08-28 | B6: MSB | C6: Chia co tuc bang CO PHIEU 100:20, GDKHQ 28/08/2026 | D6: 700 CP @ 16,000 đ | E6: 840 CP @ 13,333 đ
A7: Cảnh báo: 140 CP thuong ve TK sau ~4-6 tuan. Tinh den 15/09 CHUA XAC NHAN da ve — neu chua, lenh ban MSB chi khop duoc 700 CP.
A9: 2. LỆNH KHÔNG KHỚP (Unmatched Orders)
A10: Ngày (Date) | B10: Mã (Ticker) | C10: Kế hoạch (Plan) | D10: Kết quả (Result) | E10: Ghi chú (Note)
A11: 2026-08-20 | B11: VPI | C11: MUA 100 VPI gia toi da 63.000 | D11: KHONG KHOP | E11: Ke hoach 19/08 co nhanh bat buoc 'qua 21/08 chua khop -> mua gia thi truong'. Nhanh do DA KHONG duoc thuc hien. Lech so voi ke hoach da chot, khong phai lenh cho. User xac nhan 25/08/2026.
A13: 3. LỆNH NGOÀI LUẬT / QUY TẮC TÙY NGHI (Discretionary / Out-of-System Orders)
A14: Ngày (Date) | B14: Mã (Ticker) | C14: Loại (Type) | D14: Nội dung (Description)
A15: 2026-09-07 | B15: VHM | C15: LỆNH NGOÀI LUẬT #1 | D15: Bán 50/100 VHM @77.700 theo yêu cầu người góp vốn (không thuộc 4 quy tắc hệ thống)
A16: 2026-09-16 | B16: BSR | C16: QUY_TẮC_5 #1 | D16: Bán 100/200 BSR @31.300 — bán theo cảm quan thị trường của quỹ (lo ngại nhóm ngành dầu khí), trần 50% vị thế
